Workbook

Sheet 切替方針
B2: JP1Agent 切替方針
C4: １．JP1Agent 切替の流れ
D6: # | E6: タスク | F6: 備考
D7: 1 | E7: JobServer2へJP1 Managerのインストール(Ver:13-50-04) | F7: ETL、JobServerは分離した構成とする
D8: 2 | E8: 現行JobServer(Ver:12-10)からジョブ、バッチプログラムの移行 | F8: プログラムの修正は発生しない想定
D9: 3 | E9: JobServer2から各システムへの疎通テストを実施（DNS切替前） | F9: 新サーバー(Manager)より旧サーバー(Agent)へ接続が可能な事
D10: 4 | E10: 監視（Zabbix）設定が完了していること | F10: 杉山にて実施
D11: 5 | E11: JobServer2から各システムへの疎通テストを実施（DNS切替後） | F11: 新サーバー(Manager)より旧サーバー(Agent)へ接続が可能な事
D12: 6 | E12: 現行JP1のジョブスケジュールの停止 ※1 | F12: 既存ジョブの停止
D13: 7 | E13: 新JP1のジョブスケジュールの開始 ※1 | F13: 新ジョブの開始設定
D14: 8 | E14: 新JP1のジョブスケジュールの動作確認（初回立ち合い） | F14: ETL/Dr.SUMチーム＋運用メンバーにて実施
D15: 9 | E15: 切替判定 | F15: [動作確認の観点]に基づき実行結果の評価
D17: ※1 | E17: ジョブがサーバー間を跨って処理を行っているため上位のジョブ単位での切替を実施する。
E18: 性質ごとに以下の3種類に区分けし、その単位で切替（現行停止、新規開始）を実施する。
E19: (①⇒②⇒③の優先度で対象を選定して実施)
E21: ①ジョブネット内で１つのエージェントサーバをCALLしているもの
E22: ②ジョブネット内で複数のエージェントサーバをCALLしているもの（難易度：中）
E23: ③ジョブネット内で複数のエージェントサーバをCALLしているもの（難易度：高）

Sheet 動作確認の観点と切り戻し
B2: 動作確認の観点と切り戻し
C4: １．動作確認の方針
D6: ジョブの切替後、新サーバーでのジョブ実行結果を以下観点にて確認を行う。
D8: # | E8: 観点 | F8: 対応主担当
D9: 1 | E9: ステータス監視画面での結果が正常終了であること (異常検出完了の場合は理由を確認しスルーしてよい異常かを確認できること) | F9: ETL/Dr.SUM担当
D10: 2 | E10: 該当システムのバッチログを確認し、異常が出力されていない事 | F10: ETL/Dr.SUM担当
D11: 3 | E11: 監視（Zabbix）が機能しておりメール、Slackへの通知が行われる事 (即時の場合、WebSAM経由で電話通報ができること) | F11: 運用T担当
D12: 4 | E12: 運用チームの担当者にてダブルチェック | F12: 運用T担当
D14: 前提条件
D16: ・ | E16: すべてのジョブが移行済みで、スケジュールの設定が正しい状態になっている事
D17: ・ | E17: 監視（Zabbix）設定が完了している事
D18: ・ | E18: 各Agentサーバと疎通確認が完了している事
C21: ２．リカバリ（切り戻し）方針
D23: 問題発生時に再実行の可否、即時性の有無に応じて以下対応を行う。
D25: パターン❶ 再実行で影響が無い（即時性を求められないもの）
D26: # | E26: 対応の流れ | F26: 対応主担当
D27: 1 | E27: 問題の切り分け | F27: ETL/Dr.SUM担当
D28: 2 | E28: 問題の解消 | F28: ETL/Dr.SUM担当
D29: 3 | E29: ジョブの再実行（手動） | F29: ETL/Dr.SUM担当
D31: パターン❷ 再実行で影響が無い（即時性を求められるもの）
D32: # | E32: 対応の流れ | F32: 対応主担当
D33: 1 | E33: 新ジョブのスケジュール停止 | F33: ETL/Dr.SUM担当
D34: 2 | E34: 現行ジョブのスケジュール再開 | F34: ETL/Dr.SUM担当
D35: 3 | E35: 現状ジョブの再実行（手動） | F35: 運用T担当
D36: 4 | E36: 問題の切り分け | F36: ETL/Dr.SUM担当
D37: 5 | E37: 問題の解消 | F37: ETL/Dr.SUM担当
D38: 6 | E38: 日程再調整（原則、次回切替タイミングで再実施） | F38: ETL/Dr.SUM担当
D40: パターン❸ 再実行で問題が有る
D41: # | E41: 対応の流れ | F41: 対応主担当
D42: 1 | E42: 新ジョブのスケジュール停止 | F42: ETL/Dr.SUM担当
D43: =D42+1 -> 2 | E43: 現行ジョブのスケジュール再開 | F43: ETL/Dr.SUM担当
D44: =D43+1 -> 3 | E44: 対応方針の検討 （発生時にDHI内で協議） | F44: 運用T担当
D45: =D44+1 -> 4 | E45: リカバリ対応実施 | F45: 運用T担当
D46: =D45+1 -> 5 | E46: 問題の切り分け | F46: ETL/Dr.SUM担当
D47: =D46+1 -> 6 | E47: 問題の解消 | F47: ETL/Dr.SUM担当
D48: =D47+1 -> 7 | E48: 日程再調整（原則、次回切替タイミングで再実施） | F48: ETL/Dr.SUM担当

Sheet ジョブ一覧(概要)
B2: # | C2: JP1ジョブ(上位) | D2: ユニット数 | E2: 分類 | F2: 関連エージェントサーバー | G2: グループ | H2: 切替ショット | I2: 再実行の可否 | J2: 即時性の有無
B3: =ROW()-2 -> 1 | C3: /GFOOT/10_日次/01_HULFT | D3: =COUNTIF('ジョブ一覧(詳細)'!$C:$C,'ジョブ一覧(概要)'!$C3) -> 31 | E3: ②③ | F3: 10_DWH、N0100_02_日次、N2910_日次監視 | G3: 1 | H3: JP1⑤ | L3: ショット毎のユニット数(目安) | O3: 実施順 | P3: 実施予定日
B4: =ROW()-2 -> 2 | C4: /GFOOT/10_日次/01_LinkExpress | D4: =COUNTIF('ジョブ一覧(詳細)'!$C:$C,'ジョブ一覧(概要)'!$C4) -> 6 | E4: ① | F4: 他サーバーは該当なし | G4: 2 | H4: JP1① | L4: JP1① | M4: =SUMIF($H$3:$H$23,$L4,$D$3:$D$23) -> 25 | N4: 7 | O4: 3 | P4: 46233 | Q4: =P4 -> 46233
B5: =ROW()-2 -> 3 | C5: /GFOOT/10_日次/02_VAN | D5: =COUNTIF('ジョブ一覧(詳細)'!$C:$C,'ジョブ一覧(概要)'!$C5) -> 2 | E5: ②③ | F5: 他サーバーは該当なし？ | G5: 3 | H5: JP1① | L5: JP1② | M5: =SUMIF($H$3:$H$23,$L5,$D$3:$D$23) -> 34 | N5: 7 | O5: 1 | P5: 46219 | Q5: =P5 -> 46219
B6: =ROW()-2 -> 4 | C6: /GFOOT/10_日次/03_EC | D6: =COUNTIF('ジョブ一覧(詳細)'!$C:$C,'ジョブ一覧(概要)'!$C6) -> 6 | E6: ①？ | F6: N0100_02_日次 | G6: 4 | H6: JP1① | L6: JP1③ | M6: =SUMIF($H$3:$H$23,$L6,$D$3:$D$23) -> 18 | N6: 7 | O6: 2 | P6: 46231 | Q6: =P6 -> 46231
B7: =ROW()-2 -> 5 | C7: /GFOOT/10_日次/04_LUCKY | D7: =COUNTIF('ジョブ一覧(詳細)'!$C:$C,'ジョブ一覧(概要)'!$C7) -> 2 | E7: ① | F7: 他サーバーは該当なし | G7: 5 | H7: JP1① | L7: JP1④ | M7: =SUMIF($H$3:$H$23,$L7,$D$3:$D$23) -> 30 | N7: 8 | O7: 4 | P7: 46248 | Q7: =P7 -> 46248
B8: =ROW()-2 -> 6 | C8: /GFOOT/10_日次/05_棚卸 | D8: =COUNTIF('ジョブ一覧(詳細)'!$C:$C,'ジョブ一覧(概要)'!$C8) -> 4 | E8: ①？ | F8: 10_NAIS | G8: 1 | H8: JP1⑤ | L8: JP1⑤ | M8: =SUMIF($H$3:$H$23,$L8,$D$3:$D$23) -> 59 | N8: 8 | O8: 5 | P8: 46252 | Q8: =P8 -> 46252
B9: =ROW()-2 -> 7 | C9: /GFOOT/10_日次/06_消耗品発注 | D9: =COUNTIF('ジョブ一覧(詳細)'!$C:$C,'ジョブ一覧(概要)'!$C9) -> 3 | E9: ①？ | F9: 他サーバーは該当なし | G9: 6 | H9: JP1①
B10: =ROW()-2 -> 8 | C10: /GFOOT/10_日次/07_LCDC | D10: =COUNTIF('ジョブ一覧(詳細)'!$C:$C,'ジョブ一覧(概要)'!$C10) -> 10 | E10: ②③ | F10: 他サーバーは該当なし | G10: 7 | H10: JP1④
B11: =ROW()-2 -> 9 | C11: /GFOOT/10_日次/08_商品供給 | D11: =COUNTIF('ジョブ一覧(詳細)'!$C:$C,'ジョブ一覧(概要)'!$C11) -> 7 | E11: ②③ | F11: 他サーバーは該当なし | G11: 8 | H11: JP1④
B12: =ROW()-2 -> 10 | C12: /GFOOT/10_日次/09_取引先 | D12: =COUNTIF('ジョブ一覧(詳細)'!$C:$C,'ジョブ一覧(概要)'!$C12) -> 6 | E12: ① | F12: 他サーバーは該当なし | G12: 9 | H12: JP1①
B13: =ROW()-2 -> 11 | C13: /GFOOT/10_日次/10_DWH | D13: =COUNTIF('ジョブ一覧(詳細)'!$C:$C,'ジョブ一覧(概要)'!$C13) -> 17 | E13: ②③ | F13: 01_HULFT、05_棚卸 | G13: 1 | H13: JP1⑤
B14: =ROW()-2 -> 12 | C14: /GFOOT/10_日次/10_NAIS | D14: =COUNTIF('ジョブ一覧(詳細)'!$C:$C,'ジョブ一覧(概要)'!$C14) -> 3 | E14: ②③ | F14: 他サーバーは該当なし？ | G14: 10 | H14: JP1④
B15: =ROW()-2 -> 13 | C15: /GFOOT/10_日次/20_会計関連 | D15: =COUNTIF('ジョブ一覧(詳細)'!$C:$C,'ジョブ一覧(概要)'!$C15) -> 16 | E15: ① | F15: 30_人事関連 | G15: 11 | H15: JP1②
B16: =ROW()-2 -> 14 | C16: /GFOOT/10_日次/30_人事関連 | D16: =COUNTIF('ジョブ一覧(詳細)'!$C:$C,'ジョブ一覧(概要)'!$C16) -> 10 | E16: ②③ | F16: 20_会計関連 | G16: 11 | H16: JP1②
B17: =ROW()-2 -> 15 | C17: /GFOOT/10_日次/31_店舗 | D17: =COUNTIF('ジョブ一覧(詳細)'!$C:$C,'ジョブ一覧(概要)'!$C17) -> 7 | E17: ①？ | F17: 01_HULFT、N2910_日次監視 | G17: 1 | H17: JP1⑤
B18: =ROW()-2 -> 16 | C18: /GFOOT/10_日次/50_商品関連 | D18: =COUNTIF('ジョブ一覧(詳細)'!$C:$C,'ジョブ一覧(概要)'!$C18) -> 8 | E18: ①？ | F18: 他サーバーは該当なし | G18: 12 | H18: JP1③
B19: =ROW()-2 -> 17 | C19: /GFOOT/10_日次/51_POPシステム | D19: =COUNTIF('ジョブ一覧(詳細)'!$C:$C,'ジョブ一覧(概要)'!$C19) -> 1 | E19: ① | F19: 他サーバーは該当なし | G19: 13 | H19: JP1②
B20: =ROW()-2 -> 18 | C20: /GFOOT/10_日次/52_ASBEE+関連 | D20: =COUNTIF('ジョブ一覧(詳細)'!$C:$C,'ジョブ一覧(概要)'!$C20) -> 1 | E20: ① | F20: 他サーバーは該当なし | G20: 14 | H20: JP1②
... B23: =ROW()-2 -> 21 | C23: /GFOOT/10_日次/90_運用関連 | D23: =COUNTIF('ジョブ一覧(詳細)'!$C:$C,'ジョブ一覧(概要)'!$C23) -> 10 | E23: ① | F23: 他サーバーは該当なし | G23: 17 | H23: JP1④
B25: ※分類
C26: ①ジョブネット内で１つのエージェントサーバをCALLしているもの
C27: ②ジョブネット内で複数のエージェントサーバをCALLしているもの（難易度：中）
C28: ③ジョブネット内で複数のエージェントサーバをCALLしているもの（難易度：高）

Sheet ジョブ一覧(詳細)
A1: JP1 ジョブ一覧 | F1: 最終更新｜2026/6/26 19:05
A2: # | C2: 上位パス | D2: ユニット名 | E2: コメント | F2: 種別 | G2: 再実行 の可否 | H2: 即時性 の有無 | I2: 伝票作成に関連するジョブ | J2: ジョブ概要
A3: =ROW()-2 -> 1 | B3: =IF(ISERROR(VLOOKUP(C3,'ジョブ一覧(概要)'!$C$3:$I$23,6,FALSE)),"",VLOOKUP(C3,'ジョブ一覧(概要)'!$C$3:$I$23,6,FALSE)) | C3: /GFOOT/10_日次 | D3: N0100_01_日次_APVマスタデータ | E3: 日次_22:00 | F3: ジョブネット | K3: ①
A4: =ROW()-2 -> 2 | B4: =IF(ISERROR(VLOOKUP(C4,'ジョブ一覧(概要)'!$C$3:$I$23,6,FALSE)),"",VLOOKUP(C4,'ジョブ一覧(概要)'!$C$3:$I$23,6,FALSE)) | C4: /GFOOT/10_日次 | D4: N0100_02_日次 | E4: 日次_22:00 | F4: ジョブネット | K4: 業務的に大きいもの
A5: =ROW()-2 -> 3 | B5: =IF(ISERROR(VLOOKUP(C5,'ジョブ一覧(概要)'!$C$3:$I$23,6,FALSE)),"",VLOOKUP(C5,'ジョブ一覧(概要)'!$C$3:$I$23,6,FALSE)) | C5: /GFOOT/10_日次 | D5: N2910_日次監視 | E5: 日次_22:00 APV&ETL日次処理監視 | F5: ジョブネット
A6: =ROW()-2 -> 4 | B6: =IF(ISERROR(VLOOKUP(C6,'ジョブ一覧(概要)'!$C$3:$I$23,6,FALSE)),"",VLOOKUP(C6,'ジョブ一覧(概要)'!$C$3:$I$23,6,FALSE)) | C6: /GFOOT/10_日次 | D6: N3010_NAIS監視 | E6: 日次_01:00 NAISの日次処理監視 | F6: ジョブネット | K6: ジョブネット間でイベントの受け渡しをしているものは同時に切り替える必要がある
A7: =ROW()-2 -> 5 | B7: =IF(ISERROR(VLOOKUP(C7,'ジョブ一覧(概要)'!$C$3:$I$23,6,FALSE)),"",VLOOKUP(C7,'ジョブ一覧(概要)'!$C$3:$I$23,6,FALSE)) | C7: /GFOOT/10_日次 | D7: N3110_実行監視 | E7: 日次_17:00 前日の実行中ジョブ（送信系）があるかを監視する（N0100系を監視） | F7: ジョブネット
A8: =ROW()-2 -> 6 | B8: =IF(ISERROR(VLOOKUP(C8,'ジョブ一覧(概要)'!$C$3:$I$23,6,FALSE)),"",VLOOKUP(C8,'ジョブ一覧(概要)'!$C$3:$I$23,6,FALSE)) | C8: /GFOOT/10_日次 | D8: N4010_JP1LOG | E8: JP1日次処理ログ取得 | F8: ジョブネット
A9: =ROW()-2 -> 7 | B9: =IF(ISERROR(VLOOKUP(C9,'ジョブ一覧(概要)'!$C$3:$I$23,6,FALSE)),"",VLOOKUP(C9,'ジョブ一覧(概要)'!$C$3:$I$23,6,FALSE)) -> JP1⑤ | C9: /GFOOT/10_日次/01_HULFT | D9: メンテナンスBackUpファイル退避 | E9: 手動 | F9: ジョブネット | J9: ファイルをBOXに退避
A10: =ROW()-2 -> 8 | B10: =IF(ISERROR(VLOOKUP(C10,'ジョブ一覧(概要)'!$C$3:$I$23,6,FALSE)),"",VLOOKUP(C10,'ジョブ一覧(概要)'!$C$3:$I$23,6,FALSE)) -> JP1⑤ | C10: /GFOOT/10_日次/01_HULFT | D10: 集信_00_AEONデータ処理結果確認 | E10: 毎時_09:00~20:00 ANKYAKUTIME.dat EAS2E00A 未処理ファイルのチェック | F10: ジョブネット | I10: ◎
A11: =ROW()-2 -> 9 | B11: =IF(ISERROR(VLOOKUP(C11,'ジョブ一覧(概要)'!$C$3:$I$23,6,FALSE)),"",VLOOKUP(C11,'ジョブ一覧(概要)'!$C$3:$I$23,6,FALSE)) -> JP1⑤ | C11: /GFOOT/10_日次/01_HULFT | D11: 集信_01_AEON_HHT_v3 | E11: 10分毎_08:50~22:50 AN_HHT001.dat | F11: ジョブネット | I11: ◎
A12: =ROW()-2 -> 10 | B12: =IF(ISERROR(VLOOKUP(C12,'ジョブ一覧(概要)'!$C$3:$I$23,6,FALSE)),"",VLOOKUP(C12,'ジョブ一覧(概要)'!$C$3:$I$23,6,FALSE)) -> JP1⑤ | C12: /GFOOT/10_日次/01_HULFT | D12: 集信_01_AEON_HHT_v3_DrSum | E12: 日次_07:00~08:40 AN_HHT001.dat 売変情報付加 | F12: ジョブネット | I12: ◎
A13: =ROW()-2 -> 11 | B13: =IF(ISERROR(VLOOKUP(C13,'ジョブ一覧(概要)'!$C$3:$I$23,6,FALSE)),"",VLOOKUP(C13,'ジョブ一覧(概要)'!$C$3:$I$23,6,FALSE)) -> JP1⑤ | C13: /GFOOT/10_日次/01_HULFT | D13: 集信_02_共通POS_数量データ | E13: 15分毎_09:00~24:30 EAS2E016.txt | F13: ジョブネット | I13: ◎
A14: =ROW()-2 -> 12 | B14: =IF(ISERROR(VLOOKUP(C14,'ジョブ一覧(概要)'!$C$3:$I$23,6,FALSE)),"",VLOOKUP(C14,'ジョブ一覧(概要)'!$C$3:$I$23,6,FALSE)) -> JP1⑤ | C14: /GFOOT/10_日次/01_HULFT | D14: 集信_03_AEON_客数_v2 | E14: 毎時_09:30~19:30 【35分受信】ANKYAKUTIME.dat EAS2E00A | F14: ジョブネット | I14: ◎
A15: =ROW()-2 -> 13 | B15: =IF(ISERROR(VLOOKUP(C15,'ジョブ一覧(概要)'!$C$3:$I$23,6,FALSE)),"",VLOOKUP(C15,'ジョブ一覧(概要)'!$C$3:$I$23,6,FALSE)) -> JP1⑤ | C15: /GFOOT/10_日次/01_HULFT | D15: 集信_04_AEON_時間帯別売上 | E15: 毎時_09:40~19:40 【35分受信】ANTIME EAS2E007 | F15: ジョブネット | I15: ◎
A16: =ROW()-2 -> 14 | B16: =IF(ISERROR(VLOOKUP(C16,'ジョブ一覧(概要)'!$C$3:$I$23,6,FALSE)),"",VLOOKUP(C16,'ジョブ一覧(概要)'!$C$3:$I$23,6,FALSE)) -> JP1⑤ | C16: /GFOOT/10_日次/01_HULFT | D16: 集信_05_共通POS_POS売上_NLOG | E16: 毎時_00:00~24:00 【00分受信】EAS2E014.txt | F16: ジョブネット | I16: ◎
A17: =ROW()-2 -> 15 | B17: =IF(ISERROR(VLOOKUP(C17,'ジョブ一覧(概要)'!$C$3:$I$23,6,FALSE)),"",VLOOKUP(C17,'ジョブ一覧(概要)'!$C$3:$I$23,6,FALSE)) -> JP1⑤ | C17: /GFOOT/10_日次/01_HULFT | D17: 集信_05_共通POS_処理結果確認 | E17: 毎時_00:20~24:20 受信ファイルが残っていないことを確認用 | F17: ジョブネット | I17: ◎
A18: =ROW()-2 -> 16 | B18: =IF(ISERROR(VLOOKUP(C18,'ジョブ一覧(概要)'!$C$3:$I$23,6,FALSE)),"",VLOOKUP(C18,'ジョブ一覧(概要)'!$C$3:$I$23,6,FALSE)) -> JP1⑤ | C18: /GFOOT/10_日次/01_HULFT | D18: 集信_06_イオンコンセ_単品売上 | E18: 毎時_08:40~24:40 【40分受信】EAS2E024.txt | F18: ジョブネット | I18: ◎
A19: =ROW()-2 -> 17 | B19: =IF(ISERROR(VLOOKUP(C19,'ジョブ一覧(概要)'!$C$3:$I$23,6,FALSE)),"",VLOOKUP(C19,'ジョブ一覧(概要)'!$C$3:$I$23,6,FALSE)) -> JP1⑤ | C19: /GFOOT/10_日次/01_HULFT | D19: 集信_12_AEON_POS売上 | E19: 日次_00:40 【受信】EAS2E017.txt イオンコンセ売上 | F19: ジョブネット | I19: ◎ | J19: コンセレジからの売上データを受信する
A20: =ROW()-2 -> 18 | B20: =IF(ISERROR(VLOOKUP(C20,'ジョブ一覧(概要)'!$C$3:$I$23,6,FALSE)),"",VLOOKUP(C20,'ジョブ一覧(概要)'!$C$3:$I$23,6,FALSE)) -> JP1⑤ | C20: /GFOOT/10_日次/01_HULFT | D20: 集信_13_AEON_売変 | E20: 日次_01:00 【01:00受信】AN_BAIHEN.dat 60分で打ち切り | F20: ジョブネット | J20: コンセレジからの売変データを受信する
A21: =ROW()-2 -> 19 | B21: =IF(ISERROR(VLOOKUP(C21,'ジョブ一覧(概要)'!$C$3:$I$23,6,FALSE)),"",VLOOKUP(C21,'ジョブ一覧(概要)'!$C$3:$I$23,6,FALSE)) -> JP1⑤ | C21: /GFOOT/10_日次/01_HULFT | D21: 集信_14_AEON_客数 | E21: 日次_01:00 【01:00受信】ANKYAKUDAY.dat 60分で打ち切り | F21: ジョブネット | J21: コンセレジからの客数データを受信する
A22: =ROW()-2 -> 20 | B22: =IF(ISERROR(VLOOKUP(C22,'ジョブ一覧(概要)'!$C$3:$I$23,6,FALSE)),"",VLOOKUP(C22,'ジョブ一覧(概要)'!$C$3:$I$23,6,FALSE)) -> JP1⑤ | C22: /GFOOT/10_日次/01_HULFT | D22: 集信_21_AEONコンセ精算 | E22: 月次_05日_06:00,18日_23:30 【受信】ANKEIRI01.DAT ANKEIRI02.DAT | F22: ジョブネット | J22: イオン会計から精算データを受信する
A23: =ROW()-2 -> 21 | B23: =IF(ISERROR(VLOOKUP(C23,'ジョブ一覧(概要)'!$C$3:$I$23,6,FALSE)),"",VLOOKUP(C23,'ジョブ一覧(概要)'!$C$3:$I$23,6,FALSE)) -> JP1⑤ | C23: /GFOOT/10_日次/01_HULFT | D23: 集信_23_クレジット明細 | E23: 日次_09:00 【09:00受信】AEON_CREDIT.DAT | F23: ジョブネット | J23: イオン会計からクレジット明細を受信する
A24: =ROW()-2 -> 22 | B24: =IF(ISERROR(VLOOKUP(C24,'ジョブ一覧(概要)'!$C$3:$I$23,6,FALSE)),"",VLOOKUP(C24,'ジョブ一覧(概要)'!$C$3:$I$23,6,FALSE)) -> JP1⑤ | C24: /GFOOT/10_日次/01_HULFT | D24: 集信_31_PSS_004 | E24: 日次_22:00 【22:45受信】DC受信 | F24: ジョブネット | I24: ◎ | J24: DCから出荷実績を受信する
A25: =ROW()-2 -> 23 | B25: =IF(ISERROR(VLOOKUP(C25,'ジョブ一覧(概要)'!$C$3:$I$23,6,FALSE)),"",VLOOKUP(C25,'ジョブ一覧(概要)'!$C$3:$I$23,6,FALSE)) -> JP1⑤ | C25: /GFOOT/10_日次/01_HULFT | D25: 集信_32_PSS_005-006 | E25: 日次_00:05 【00:05受信】東西日本LC | F25: ジョブネット | I25: ◎ | J25: 東西LCから出荷実績を受信する
A26: =ROW()-2 -> 24 | B26: =IF(ISERROR(VLOOKUP(C26,'ジョブ一覧(概要)'!$C$3:$I$23,6,FALSE)),"",VLOOKUP(C26,'ジョブ一覧(概要)'!$C$3:$I$23,6,FALSE)) -> JP1⑤ | C26: /GFOOT/10_日次/01_HULFT | D26: 集信_34_ASM_出荷実績 | E26: 日次_18:00 【23:00受信】ASM_出荷情報 | F26: ジョブネット | J26: ASM取引先から出荷実績を受領する
A27: =ROW()-2 -> 25 | B27: =IF(ISERROR(VLOOKUP(C27,'ジョブ一覧(概要)'!$C$3:$I$23,6,FALSE)),"",VLOOKUP(C27,'ジョブ一覧(概要)'!$C$3:$I$23,6,FALSE)) -> JP1⑤ | C27: /GFOOT/10_日次/01_HULFT | D27: 集信_35_打鍵・返品・違算データ | E27: 月次_05日_11:00 【11:00受信】EAS2E01E.csv EAS2E01F.csv EAS2E020.csv | F27: ジョブネット | J27: イオンからデータを受信するのみ
A28: =ROW()-2 -> 26 | B28: =IF(ISERROR(VLOOKUP(C28,'ジョブ一覧(概要)'!$C$3:$I$23,6,FALSE)),"",VLOOKUP(C28,'ジョブ一覧(概要)'!$C$3:$I$23,6,FALSE)) -> JP1⑤ | C28: /GFOOT/10_日次/01_HULFT | D28: 配信_11_AEON_商品マスタ | E28: 日次_21:50 【01:00送信】ANPLUSND.DAT イオンコンセ | F28: ジョブネット | J28: イオンレジ向けに商品マスタを送信する
A29: =ROW()-2 -> 27 | B29: =IF(ISERROR(VLOOKUP(C29,'ジョブ一覧(概要)'!$C$3:$I$23,6,FALSE)),"",VLOOKUP(C29,'ジョブ一覧(概要)'!$C$3:$I$23,6,FALSE)) -> JP1⑤ | C29: /GFOOT/10_日次/01_HULFT | D29: 配信_11_AEON_商品マスタ_事前 | E29: 日次_15:00 【17:00送信】ANPLUSND.DAT イオンコンセ | F29: ジョブネット | J29: イオンレジ向けに商品マスタを送信する
A30: =ROW()-2 -> 28 | B30: =IF(ISERROR(VLOOKUP(C30,'ジョブ一覧(概要)'!$C$3:$I$23,6,FALSE)),"",VLOOKUP(C30,'ジョブ一覧(概要)'!$C$3:$I$23,6,FALSE)) -> JP1⑤ | C30: /GFOOT/10_日次/01_HULFT | D30: 配信_12_共通POS向け_レジマスタ | E30: 日次_23:00 【23:25送信】EAS2E10.txt EAS2E0E.txt | F30: ジョブネット | J30: 自社レジに社員マスタを送信する
A31: =ROW()-2 -> 29 | B31: =IF(ISERROR(VLOOKUP(C31,'ジョブ一覧(概要)'!$C$3:$I$23,6,FALSE)),"",VLOOKUP(C31,'ジョブ一覧(概要)'!$C$3:$I$23,6,FALSE)) -> JP1⑤ | C31: /GFOOT/10_日次/01_HULFT | D31: 配信_21_AOC_SAPへのデータ連携 | E31: 日次_02:15 【09:00送信】adr3wlx.txt イオン経理連携 | F31: ジョブネット | J31: イオン会計（SAP）にデータを送信する
A32: =ROW()-2 -> 30 | B32: =IF(ISERROR(VLOOKUP(C32,'ジョブ一覧(概要)'!$C$3:$I$23,6,FALSE)),"",VLOOKUP(C32,'ジョブ一覧(概要)'!$C$3:$I$23,6,FALSE)) -> JP1⑤ | C32: /GFOOT/10_日次/01_HULFT | D32: 配信_22_AOC_オーナーズ実績 | E32: 日次_13:00 【13:00送信】OWNER_AEON.dat イオン経理連携（毎月3日） | F32: ジョブネット | J32: イオンにオーナーズ実績を送信する
A33: =ROW()-2 -> 31 | B33: =IF(ISERROR(VLOOKUP(C33,'ジョブ一覧(概要)'!$C$3:$I$23,6,FALSE)),"",VLOOKUP(C33,'ジョブ一覧(概要)'!$C$3:$I$23,6,FALSE)) -> JP1⑤ | C33: /GFOOT/10_日次/01_HULFT | D33: 配信_30_PSS | E33: 日次_21:50 【05:50送信】PSS001,PSS002,PSS003 | F33: ジョブネット | I33: ◎ | J33: PSS向けにデータを送信
A34: =ROW()-2 -> 32 | B34: =IF(ISERROR(VLOOKUP(C34,'ジョブ一覧(概要)'!$C$3:$I$23,6,FALSE)),"",VLOOKUP(C34,'ジョブ一覧(概要)'!$C$3:$I$23,6,FALSE)) -> JP1⑤ | C34: /GFOOT/10_日次/01_HULFT | D34: 配信_31_PSS_009 | E34: 日次_21:50 【09:00送信】PSS009 | F34: ジョブネット | I34: ◎ | J34: PSS向けにデータを送信
A35: =ROW()-2 -> 33 | B35: =IF(ISERROR(VLOOKUP(C35,'ジョブ一覧(概要)'!$C$3:$I$23,6,FALSE)),"",VLOOKUP(C35,'ジョブ一覧(概要)'!$C$3:$I$23,6,FALSE)) -> JP1⑤ | C35: /GFOOT/10_日次/01_HULFT | D35: 配信_32_AEONTopValue向け発注 | E35: 日次_21:50 【09:00送信】VANSENDH_TV | F35: ジョブネット | I35: ◎ | J35: イオンTOPVALUEに発注データを送信
A36: =ROW()-2 -> 34 | B36: =IF(ISERROR(VLOOKUP(C36,'ジョブ一覧(概要)'!$C$3:$I$23,6,FALSE)),"",VLOOKUP(C36,'ジョブ一覧(概要)'!$C$3:$I$23,6,FALSE)) -> JP1⑤ | C36: /GFOOT/10_日次/01_HULFT | D36: 配信_33_ASM向け_発注検収返品デ | E36: 日次_21:50 【06:00送信】C:\HFT\SND\VANSENDx_ASM.dat | F36: ジョブネット | I36: ◎ | J36: ASM取引先から出荷実績データを受信する
A37: =ROW()-2 -> 35 | B37: =IF(ISERROR(VLOOKUP(C37,'ジョブ一覧(概要)'!$C$3:$I$23,6,FALSE)),"",VLOOKUP(C37,'ジョブ一覧(概要)'!$C$3:$I$23,6,FALSE)) -> JP1⑤ | C37: /GFOOT/10_日次/01_HULFT | D37: 配信_34_LOMOS_自動値札貼付 | E37: 日次_21:45 【07:00送信】TICKET_SND_001.DATA 東・西・北海道LC向け | F37: ジョブネット | J37: ナンバリングチケットを東西LC、北海道LCに送信
A38: =ROW()-2 -> 36 | B38: =IF(ISERROR(VLOOKUP(C38,'ジョブ一覧(概要)'!$C$3:$I$23,6,FALSE)),"",VLOOKUP(C38,'ジョブ一覧(概要)'!$C$3:$I$23,6,FALSE)) -> JP1⑤ | C38: /GFOOT/10_日次/01_HULFT | D38: 配信_40_ASM_販社支払データ | E38: 月次_01日_15:00 【15:00送信】SHRI_DATA_ASM.dat | F38: ジョブネット | J38: ASMに支払データを送信する
A39: =ROW()-2 -> 37 | B39: =IF(ISERROR(VLOOKUP(C39,'ジョブ一覧(概要)'!$C$3:$I$23,6,FALSE)),"",VLOOKUP(C39,'ジョブ一覧(概要)'!$C$3:$I$23,6,FALSE)) -> JP1⑤ | C39: /GFOOT/10_日次/01_HULFT | D39: 配信_50_AEON_経営DB | E39: 日次_02:00 【06:01送信】イオン経営ＤＢ向けデータ送信 | F39: ジョブネット | I39: ◎ | J39: イオン向けに経営DBデータを送信する
A40: =ROW()-2 -> 38 | B40: =IF(ISERROR(VLOOKUP(C40,'ジョブ一覧(概要)'!$C$3:$I$23,6,FALSE)),"",VLOOKUP(C40,'ジョブ一覧(概要)'!$C$3:$I$23,6,FALSE)) -> JP1① | C40: /GFOOT/10_日次/01_LinkExpress | D40: 00_店舗HHT用_SoketFile出力_OCI | E40: 日次 07:40 ALL_PLU_SOCKET | F40: ジョブネット
...

Sheet (参考)イベントの繋がり
B2: 送信側 | C2: 受信側
B3: 01_HULFT | C3: 10_DWH
B4: 01_HULFT | C4: N0100_02_日次
B5: 01_HULFT | C5: N2910_日次監視
B6: 01_HULFT | C6: 該当なし
B7: 03_EC | C7: N0100_02_日次
B8: 05_棚卸 | C8: 10_NAIS
B9: 08_商品供給 | C9: 08_商品供給
B10: 10_DWH | C10: 01_HULFT
B11: 10_DWH | C11: 05_棚卸
B12: 10_DWH | C12: 10_DWH
B13: 10_DWH | C13: 該当なし
... B28: N3010_NAIS監視 | C28: 10_DWH

Sheet (参考)イベント受信待ち
B1: (参考)イベント受信待ち | D1: 46199.795 | E1: jp1admin | F1: TYCLDS30 | I1: 上位パス | M1: 受信
A2: イベントID | B2: # | C2: ユニット名 | D2: 上位パス | E2: コメント | F2: 種別 | G2: イベントID | I2: 階層1 | J2: 階層2 | K2: 階層3
A3: 7FFFA002 | B3: =ROW()-2 -> 1 | C3: APVマスタデータ出力完了_002 | D3: /GFOOT/10_日次/01_HULFT/配信_11_AEON_商品マスタ | E3: 7FFFA002_10_日次/N0100_01_日次_APVマスタデータ | F3: JP1イベント受信監視 | G3: 7FFFA002 | I3: {=INDEX(_xlfn.TEXTSPLIT($D3,"/"),2)} -> GFOOT | J3: {=INDEX(_xlfn.TEXTSPLIT($D3,"/"),3)} -> 10_日次 | K3: {=INDEX(_xlfn.TEXTSPLIT($D3,"/"),4)} -> 01_HULFT
A4: 7FFFA708 | B4: =ROW()-2 -> 2 | C4: 店舗売価マスタ_BO転入完了 | D4: /GFOOT/10_日次/01_HULFT/配信_11_AEON_商品マスタ | E4: 7FFFA708_10_日次/10_DWH/12_店舗売価マスタ更新_BO転入 | F4: JP1イベント受信監視 | G4: 7FFFA708 | I4: {=INDEX(_xlfn.TEXTSPLIT($D4,"/"),2)} -> GFOOT | J4: {=INDEX(_xlfn.TEXTSPLIT($D4,"/"),3)} -> 10_日次 | K4: {=INDEX(_xlfn.TEXTSPLIT($D4,"/"),4)} -> 01_HULFT
A5: 7FFFA709 | B5: =ROW()-2 -> 3 | C5: 売変データ更新完了 | D5: /GFOOT/10_日次/01_HULFT/配信_11_AEON_商品マスタ | E5: 7FFFA709 10_日次/31_店舗/01_自動売変 | F5: JP1イベント受信監視 | G5: 7FFFA709 | I5: {=INDEX(_xlfn.TEXTSPLIT($D5,"/"),2)} -> GFOOT | J5: {=INDEX(_xlfn.TEXTSPLIT($D5,"/"),3)} -> 10_日次 | K5: {=INDEX(_xlfn.TEXTSPLIT($D5,"/"),4)} -> 01_HULFT
A6: 7FFFA002 | B6: =ROW()-2 -> 4 | C6: 売変_事前確認_完了 | D6: /GFOOT/10_日次/01_HULFT/配信_11_AEON_商品マスタ_事前 | E6: 7FFFA002_10_日次/N0100_01_日次_APVマスタデータ | F6: JP1イベント受信監視 | G6: 7FFFA002 | I6: {=INDEX(_xlfn.TEXTSPLIT($D6,"/"),2)} -> GFOOT | J6: {=INDEX(_xlfn.TEXTSPLIT($D6,"/"),3)} -> 10_日次 | K6: {=INDEX(_xlfn.TEXTSPLIT($D6,"/"),4)} -> 01_HULFT
A7: 7FFFA601 | B7: =ROW()-2 -> 5 | C7: PSS001作成完了_受_601 | D7: /GFOOT/10_日次/01_HULFT/配信_30_PSS | E7: 7FFFA601_イベント受信(PSS001作成完了) | F7: JP1イベント受信監視 | G7: 7FFFA601 | I7: {=INDEX(_xlfn.TEXTSPLIT($D7,"/"),2)} -> GFOOT | J7: {=INDEX(_xlfn.TEXTSPLIT($D7,"/"),3)} -> 10_日次 | K7: {=INDEX(_xlfn.TEXTSPLIT($D7,"/"),4)} -> 01_HULFT
A8: 7FFFA602 | B8: =ROW()-2 -> 6 | C8: PSS002作成完了_受_602 | D8: /GFOOT/10_日次/01_HULFT/配信_30_PSS | E8: 7FFFA602_イベント受信(PSS002作成完了) | F8: JP1イベント受信監視 | G8: 7FFFA602 | I8: {=INDEX(_xlfn.TEXTSPLIT($D8,"/"),2)} -> GFOOT | J8: {=INDEX(_xlfn.TEXTSPLIT($D8,"/"),3)} -> 10_日次 | K8: {=INDEX(_xlfn.TEXTSPLIT($D8,"/"),4)} -> 01_HULFT
A9: 7FFFA603 | B9: =ROW()-2 -> 7 | C9: PSS003作成完了_受_603 | D9: /GFOOT/10_日次/01_HULFT/配信_30_PSS | E9: 7FFFA603_イベント受信(PSS003作成完了) | F9: JP1イベント受信監視 | G9: 7FFFA603 | I9: {=INDEX(_xlfn.TEXTSPLIT($D9,"/"),2)} -> GFOOT | J9: {=INDEX(_xlfn.TEXTSPLIT($D9,"/"),3)} -> 10_日次 | K9: {=INDEX(_xlfn.TEXTSPLIT($D9,"/"),4)} -> 01_HULFT
A10: 7FFFA609 | B10: =ROW()-2 -> 8 | C10: PSS009作成完了_受_609 | D10: /GFOOT/10_日次/01_HULFT/配信_31_PSS_009 | E10: 7FFFA609_イベント受信(PSS009作成完了) | F10: JP1イベント受信監視 | G10: 7FFFA609 | I10: {=INDEX(_xlfn.TEXTSPLIT($D10,"/"),2)} -> GFOOT | J10: {=INDEX(_xlfn.TEXTSPLIT($D10,"/"),3)} -> 10_日次 | K10: {=INDEX(_xlfn.TEXTSPLIT($D10,"/"),4)} -> 01_HULFT
A11: 7FFFA539 | B11: =ROW()-2 -> 9 | C11: VANSENDH_TV作成完了_受539 | D11: /GFOOT/10_日次/01_HULFT/配信_32_AEONTopValue向け発注 | E11: 7FFFA539_イベント受信(VANSENDH_TV作成完了) 7:50打ち切り | F11: JP1イベント受信監視 | G11: 7FFFA539 | I11: {=INDEX(_xlfn.TEXTSPLIT($D11,"/"),2)} -> GFOOT | J11: {=INDEX(_xlfn.TEXTSPLIT($D11,"/"),3)} -> 10_日次 | K11: {=INDEX(_xlfn.TEXTSPLIT($D11,"/"),4)} -> 01_HULFT
A12: 7FFFA539 | B12: =ROW()-2 -> 10 | C12: 受539_発注データ作成終了 | D12: /GFOOT/10_日次/01_HULFT/配信_33_ASM向け_発注検収返品デ | E12: 7FFFA539_VAN_APV_VANSENDH.bat待ち_イベント受信 | F12: JP1イベント受信監視 | G12: 7FFFA539 | I12: {=INDEX(_xlfn.TEXTSPLIT($D12,"/"),2)} -> GFOOT | J12: {=INDEX(_xlfn.TEXTSPLIT($D12,"/"),3)} -> 10_日次 | K12: {=INDEX(_xlfn.TEXTSPLIT($D12,"/"),4)} -> 01_HULFT
A13: 7FFFA540 | B13: =ROW()-2 -> 11 | C13: 受540_検収・返品データ作成終了 | D13: /GFOOT/10_日次/01_HULFT/配信_33_ASM向け_発注検収返品デ | E13: 7FFFA540_VAN_APV_VANSEND.bat待ち_イベント受信 | F13: JP1イベント受信監視 | G13: 7FFFA540 | I13: {=INDEX(_xlfn.TEXTSPLIT($D13,"/"),2)} -> GFOOT | J13: {=INDEX(_xlfn.TEXTSPLIT($D13,"/"),3)} -> 10_日次 | K13: {=INDEX(_xlfn.TEXTSPLIT($D13,"/"),4)} -> 01_HULFT
A14: 7FFFA702 | B14: =ROW()-2 -> 12 | C14: 商品ＲＭ更新処理完了_702 | D14: /GFOOT/10_日次/01_HULFT/配信_34_LOMOS_自動値札貼付 | E14: 7FFFA702_商品ＲＭ更新処理完了 9:00 まで監視 | F14: JP1イベント受信監視 | G14: 7FFFA702 | I14: {=INDEX(_xlfn.TEXTSPLIT($D14,"/"),2)} -> GFOOT | J14: {=INDEX(_xlfn.TEXTSPLIT($D14,"/"),3)} -> 10_日次 | K14: {=INDEX(_xlfn.TEXTSPLIT($D14,"/"),4)} -> 01_HULFT
... A16: 7FFFA701 | B16: =ROW()-2 -> 14 | C16: APV->DWH取込処理終了_7FFFA701 | D16: /GFOOT/10_日次/01_HULFT/配信_50_AEON_経営DB | E16: 7FFFA701 APV->DWH取込処理終了イベント受信 | F16: JP1イベント受信監視 | G16: 7FFFA701 | I16: {=INDEX(_xlfn.TEXTSPLIT($D16,"/"),2)} -> GFOOT | J16: {=INDEX(_xlfn.TEXTSPLIT($D16,"/"),3)} -> 10_日次 | K16: {=INDEX(_xlfn.TEXTSPLIT($D16,"/"),4)} -> 01_HULFT
B17: =ROW()-2 -> 15 | C17: 店舗売価マスタ更新 | D17: /GFOOT/10_日次/01_LinkExpress/11_商品マスタ_03_作成送信_売変 | F17: JP1イベント受信監視 | I17: {=INDEX(_xlfn.TEXTSPLIT($D17,"/"),2)} -> GFOOT | J17: {=INDEX(_xlfn.TEXTSPLIT($D17,"/"),3)} -> 10_日次 | K17: {=INDEX(_xlfn.TEXTSPLIT($D17,"/"),4)} -> 01_LinkExpress
A18: 7FFFA709 | B18: =ROW()-2 -> 16 | C18: 売変データ更新完了 | D18: /GFOOT/10_日次/01_LinkExpress/11_商品マスタ_03_作成送信_売変 | E18: 7FFFA709 10_日次/31_店舗/01_自動売変 | F18: JP1イベント受信監視 | G18: 7FFFA709 | I18: {=INDEX(_xlfn.TEXTSPLIT($D18,"/"),2)} -> GFOOT | J18: {=INDEX(_xlfn.TEXTSPLIT($D18,"/"),3)} -> 10_日次 | K18: {=INDEX(_xlfn.TEXTSPLIT($D18,"/"),4)} -> 01_LinkExpress
A19: 7FFFA540 | B19: =ROW()-2 -> 17 | C19: 検収返品作成完了_7FFFA540 | D19: /GFOOT/10_日次/02_VAN/11_取引先への送信_VAN | E19: 7FFFA540_検収返品作成完了 | F19: JP1イベント受信監視 | G19: 7FFFA540 | I19: {=INDEX(_xlfn.TEXTSPLIT($D19,"/"),2)} -> GFOOT | J19: {=INDEX(_xlfn.TEXTSPLIT($D19,"/"),3)} -> 10_日次 | K19: {=INDEX(_xlfn.TEXTSPLIT($D19,"/"),4)} -> 02_VAN
A20: 7FFFA539 | B20: =ROW()-2 -> 18 | C20: 発注作成完了_7FFFA539 | D20: /GFOOT/10_日次/02_VAN/11_取引先への送信_VAN | E20: 7FFFA539_発注作成完了 | F20: JP1イベント受信監視 | G20: 7FFFA539 | I20: {=INDEX(_xlfn.TEXTSPLIT($D20,"/"),2)} -> GFOOT | J20: {=INDEX(_xlfn.TEXTSPLIT($D20,"/"),3)} -> 10_日次 | K20: {=INDEX(_xlfn.TEXTSPLIT($D20,"/"),4)} -> 02_VAN
A21: 7FFFA002 | B21: =ROW()-2 -> 19 | C21: APVマスタデータ出力完了_002 | D21: /GFOOT/10_日次/03_EC/001_商品マスタ | E21: 7FFFA002_10_日次/N0100_01_日次_APVマスタデータ | F21: JP1イベント受信監視 | G21: 7FFFA002 | I21: {=INDEX(_xlfn.TEXTSPLIT($D21,"/"),2)} -> GFOOT | J21: {=INDEX(_xlfn.TEXTSPLIT($D21,"/"),3)} -> 10_日次 | K21: {=INDEX(_xlfn.TEXTSPLIT($D21,"/"),4)} -> 03_EC
A22: 7FFFA709 | B22: =ROW()-2 -> 20 | C22: BOOK売変 | D22: /GFOOT/10_日次/03_EC/001_商品マスタ | E22: 7FFFA709_10_日次/N0100_01_日次_APVマスタデータ | F22: JP1イベント受信監視 | G22: 7FFFA709 | I22: {=INDEX(_xlfn.TEXTSPLIT($D22,"/"),2)} -> GFOOT | J22: {=INDEX(_xlfn.TEXTSPLIT($D22,"/"),3)} -> 10_日次 | K22: {=INDEX(_xlfn.TEXTSPLIT($D22,"/"),4)} -> 03_EC
A23: 7FFFA539 | B23: =ROW()-2 -> 21 | C23: APV発注データ作成完了_7FFFA539 | D23: /GFOOT/10_日次/03_EC/002_在庫データ | E23: 7FFFA539 | F23: JP1イベント受信監視 | G23: 7FFFA539 | I23: {=INDEX(_xlfn.TEXTSPLIT($D23,"/"),2)} -> GFOOT | J23: {=INDEX(_xlfn.TEXTSPLIT($D23,"/"),3)} -> 10_日次 | K23: {=INDEX(_xlfn.TEXTSPLIT($D23,"/"),4)} -> 03_EC
A24: 7FFFA701 | B24: =ROW()-2 -> 22 | C24: APV発注データ作成完了_7FFFA539 | D24: /GFOOT/10_日次/03_EC/003_入荷予定データ | E24: 7FFFA701 APV->DWH取込処理終了イベント受信 | F24: JP1イベント受信監視 | G24: 7FFFA701 | I24: {=INDEX(_xlfn.TEXTSPLIT($D24,"/"),2)} -> GFOOT | J24: {=INDEX(_xlfn.TEXTSPLIT($D24,"/"),3)} -> 10_日次 | K24: {=INDEX(_xlfn.TEXTSPLIT($D24,"/"),4)} -> 03_EC
A25: 7FFFA002 | B25: =ROW()-2 -> 23 | C25: APVマスタ更新終了 | D25: /GFOOT/10_日次/03_EC/030_NDAM | E25: 7FFFA002 イベント受信(APVマスタ更新) | F25: JP1イベント受信監視 | G25: 7FFFA002 | I25: {=INDEX(_xlfn.TEXTSPLIT($D25,"/"),2)} -> GFOOT | J25: {=INDEX(_xlfn.TEXTSPLIT($D25,"/"),3)} -> 10_日次 | K25: {=INDEX(_xlfn.TEXTSPLIT($D25,"/"),4)} -> 03_EC
A26: 7FFFA703 | B26: =ROW()-2 -> 24 | C26: 店舗売価マスタ更新：703 | D26: /GFOOT/10_日次/05_棚卸/商品マスタ送信_v2.0 | E26: 7FFFA703_店舗売価マスタ更新処理終了 360分監視 | F26: JP1イベント受信監視 | G26: 7FFFA703 | I26: {=INDEX(_xlfn.TEXTSPLIT($D26,"/"),2)} -> GFOOT | J26: {=INDEX(_xlfn.TEXTSPLIT($D26,"/"),3)} -> 10_日次 | K26: {=INDEX(_xlfn.TEXTSPLIT($D26,"/"),4)} -> 05_棚卸
A27: 7FFFA511 | B27: =ROW()-2 -> 25 | C27: 消耗品発注作成完了_受_7FFFA511 | D27: /GFOOT/10_日次/06_消耗品発注/01_発注データコピー | E27: 7FFFA511 | F27: JP1イベント受信監視 | G27: 7FFFA511 | I27: {=INDEX(_xlfn.TEXTSPLIT($D27,"/"),2)} -> GFOOT | J27: {=INDEX(_xlfn.TEXTSPLIT($D27,"/"),3)} -> 10_日次 | K27: {=INDEX(_xlfn.TEXTSPLIT($D27,"/"),4)} -> 06_消耗品発注
A28: 584 | B28: =ROW()-2 -> 26 | C28: 受領データ受信_受584 | D28: /GFOOT/10_日次/08_商品供給/11_商品供給_発注データ受信 | E28: 584_イベント受信(受領データ) | F28: JP1イベント受信監視 | G28: 584 | I28: {=INDEX(_xlfn.TEXTSPLIT($D28,"/"),2)} -> GFOOT | J28: {=INDEX(_xlfn.TEXTSPLIT($D28,"/"),3)} -> 10_日次 | K28: {=INDEX(_xlfn.TEXTSPLIT($D28,"/"),4)} -> 08_商品供給
A29: 583 | B29: =ROW()-2 -> 27 | C29: 発注データ受信_受583 | D29: /GFOOT/10_日次/08_商品供給/11_商品供給_発注データ受信 | E29: 583_イベント受信(発注データ) | F29: JP1イベント受信監視 | G29: 583 | I29: {=INDEX(_xlfn.TEXTSPLIT($D29,"/"),2)} -> GFOOT | J29: {=INDEX(_xlfn.TEXTSPLIT($D29,"/"),3)} -> 10_日次 | K29: {=INDEX(_xlfn.TEXTSPLIT($D29,"/"),4)} -> 08_商品供給
A30: 7FFFA539 | B30: =ROW()-2 -> 28 | C30: 発注データ作成 | D30: /GFOOT/10_日次/08_商品供給/13_商品供給_発注データ集約 | E30: 7FFFA539_イベント受信(発注データ) | F30: JP1イベント受信監視 | G30: 7FFFA539 | I30: {=INDEX(_xlfn.TEXTSPLIT($D30,"/"),2)} -> GFOOT | J30: {=INDEX(_xlfn.TEXTSPLIT($D30,"/"),3)} -> 10_日次 | K30: {=INDEX(_xlfn.TEXTSPLIT($D30,"/"),4)} -> 08_商品供給
A31: 7FFFA002 | B31: =ROW()-2 -> 29 | C31: イベント受信：7FFFA002 | D31: /GFOOT/10_日次/08_商品供給/14.商品供給_商品マスタ出力 | E31: 7FFFA002 イベント受信(N370120_ETL完了)J014310I_受574 | F31: JP1イベント受信監視 | G31: 7FFFA002 | I31: {=INDEX(_xlfn.TEXTSPLIT($D31,"/"),2)} -> GFOOT | J31: {=INDEX(_xlfn.TEXTSPLIT($D31,"/"),3)} -> 10_日次 | K31: {=INDEX(_xlfn.TEXTSPLIT($D31,"/"),4)} -> 08_商品供給
A32: 7FFFA701 | B32: =ROW()-2 -> 30 | C32: APV->DWH取込完了_7FFFA701 | D32: /GFOOT/10_日次/09_取引先/20_NIKE提供データ | E32: 7FFFA701 APV->DWH取込処理終了イベント受信 | F32: JP1イベント受信監視 | G32: 7FFFA701 | I32: {=INDEX(_xlfn.TEXTSPLIT($D32,"/"),2)} -> GFOOT | J32: {=INDEX(_xlfn.TEXTSPLIT($D32,"/"),3)} -> 10_日次 | K32: {=INDEX(_xlfn.TEXTSPLIT($D32,"/"),4)} -> 09_取引先
A33: 7FFFA703 | B33: =ROW()-2 -> 31 | C33: 店舗売価マスタ作成完了 | D33: /GFOOT/10_日次/09_取引先/20_NIKE提供データ | E33: 7FFFA703_店舗売価マスタ更新処理終了 240分監視 | F33: JP1イベント受信監視 | G33: 7FFFA703 | I33: {=INDEX(_xlfn.TEXTSPLIT($D33,"/"),2)} -> GFOOT | J33: {=INDEX(_xlfn.TEXTSPLIT($D33,"/"),3)} -> 10_日次 | K33: {=INDEX(_xlfn.TEXTSPLIT($D33,"/"),4)} -> 09_取引先
A34: 7FFFA706 | B34: =ROW()-2 -> 32 | C34: NLOG受信後処理_受_706 | D34: /GFOOT/10_日次/10_DWH/01_NLOG受信後処理_Dr.Sum更新 | E34: 7FFFA706 NLOG受信後処理 | F34: JP1イベント受信監視 | G34: 7FFFA706 | I34: {=INDEX(_xlfn.TEXTSPLIT($D34,"/"),2)} -> GFOOT | J34: {=INDEX(_xlfn.TEXTSPLIT($D34,"/"),3)} -> 10_日次 | K34: {=INDEX(_xlfn.TEXTSPLIT($D34,"/"),4)} -> 10_DWH
A35: TS | B35: =ROW()-2 -> 33 | C35: TS_時間帯別実績更新後_受_707 | D35: /GFOOT/10_日次/10_DWH/02_売上速報_ver2.0 | E35: TS_時間帯別実績更新後 | F35: JP1イベント受信監視 | G35: TS | I35: {=INDEX(_xlfn.TEXTSPLIT($D35,"/"),2)} -> GFOOT | J35: {=INDEX(_xlfn.TEXTSPLIT($D35,"/"),3)} -> 10_日次 | K35: {=INDEX(_xlfn.TEXTSPLIT($D35,"/"),4)} -> 10_DWH
A36: 7FFFA700 | B36: =ROW()-2 -> 34 | C36: AP-V取込完了_7FFFA700 | D36: /GFOOT/10_日次/10_DWH/15_DWH_Dr.Sum更新 | E36: 7FFFA700 9時10分に通知 | F36: JP1イベント受信監視 | G36: 7FFFA700 | I36: {=INDEX(_xlfn.TEXTSPLIT($D36,"/"),2)} -> GFOOT | J36: {=INDEX(_xlfn.TEXTSPLIT($D36,"/"),3)} -> 10_日次 | K36: {=INDEX(_xlfn.TEXTSPLIT($D36,"/"),4)} -> 10_DWH
A37: 7FFFA539 | B37: =ROW()-2 -> 35 | C37: APV発注データ作成完了_7FFFA539 | D37: /GFOOT/10_日次/10_DWH/15_DWH_Dr.Sum更新 | E37: 7FFFA539 9時50分に通知 | F37: JP1イベント受信監視 | G37: 7FFFA539 | I37: {=INDEX(_xlfn.TEXTSPLIT($D37,"/"),2)} -> GFOOT | J37: {=INDEX(_xlfn.TEXTSPLIT($D37,"/"),3)} -> 10_日次 | K37: {=INDEX(_xlfn.TEXTSPLIT($D37,"/"),4)} -> 10_DWH
A38: 7FFFA592 | B38: =ROW()-2 -> 36 | C38: 発注対象ＣＦ完了 | D38: /GFOOT/10_日次/10_DWH/15_DWH_Dr.Sum更新 | E38: 7FFFA592 7時50分に通知 | F38: JP1イベント受信監視 | G38: 7FFFA592 | I38: {=INDEX(_xlfn.TEXTSPLIT($D38,"/"),2)} -> GFOOT | J38: {=INDEX(_xlfn.TEXTSPLIT($D38,"/"),3)} -> 10_日次 | K38: {=INDEX(_xlfn.TEXTSPLIT($D38,"/"),4)} -> 10_DWH
A39: 7FFFA299 | B39: =ROW()-2 -> 37 | C39: 受299_AUTOMAINOK_DWH更新トリガ | D39: /GFOOT/10_日次/10_DWH/16_DWH_NIS関連処理 | E39: 7FFFA299_イベント受信（ID:299） 360⇒480 | F39: JP1イベント受信監視 | G39: 7FFFA299 | I39: {=INDEX(_xlfn.TEXTSPLIT($D39,"/"),2)} -> GFOOT | J39: {=INDEX(_xlfn.TEXTSPLIT($D39,"/"),3)} -> 10_日次 | K39: {=INDEX(_xlfn.TEXTSPLIT($D39,"/"),4)} -> 10_DWH
A40: 705 | B40: =ROW()-2 -> 38 | C40: 週別店別単品実績更新終了 | D40: /GFOOT/10_日次/10_DWH/18_DWH_Sim | E40: 705 本番DWHサマリ作成処理終了(旧705→1705→7FFFA705) | F40: JP1イベント受信監視 | G40: 705 | I40: {=INDEX(_xlfn.TEXTSPLIT($D40,"/"),2)} -> GFOOT | J40: {=INDEX(_xlfn.TEXTSPLIT($D40,"/"),3)} -> 10_日次 | K40: {=INDEX(_xlfn.TEXTSPLIT($D40,"/"),4)} -> 10_DWH
A41: 7FFFA705 | B41: =ROW()-2 -> 39 | C41: 週別店別単品実績更新終了 | D41: /GFOOT/10_日次/10_DWH/21_週別_DrSum_レポート更新 | E41: 7FFFA705 週別店別単品実績の更新完了待ち | F41: JP1イベント受信監視 | G41: 7FFFA705 | I41: {=INDEX(_xlfn.TEXTSPLIT($D41,"/"),2)} -> GFOOT | J41: {=INDEX(_xlfn.TEXTSPLIT($D41,"/"),3)} -> 10_日次 | K41: {=INDEX(_xlfn.TEXTSPLIT($D41,"/"),4)} -> 10_DWH
...

Sheet (参考)イベント送信待ち
A1: (参考)イベント送信待ち | C1: 46199.796 | D1: jp1admin | E1: TYCLDS30 | H1: イベント受信待ち | M1: 送信側の上位パス | Q1: 受信側の上位パス
A2: # | B2: ユニット名 | C2: 上位パス | D2: コメント | E2: 種別 | F2: イベントID | H2: No | I2: ユニット名 | J2: 上位パス | K2: 備考 | M2: 階層1 | N2: 階層2 | O2: 階層3 | Q2: 階層1 | R2: 階層2 | S2: 階層3
A3: =ROW()-2 -> 1 | B3: 送711_AEON_HHT処理完了イベント | C3: /GFOOT/10_日次/01_HULFT/集信_01_AEON_HHT_v3/Dr.Sum更新 | D3: 7FFFA711 AEON_HHT処理完了イベント | E3: JP1イベント送信 | F3: 7FFFA711 | H3: =IF(ISERROR(VLOOKUP(F3,'(参考)イベント受信待ち'!A:F,2,FALSE)),"該当無し",VLOOKUP(F3,'(参考)イベント受信待ち'!A:F,2,FALSE)) -> 該当無し | I3: =IF(ISERROR(VLOOKUP(F3,'(参考)イベント受信待ち'!A:F,3,FALSE)),"該当無し",VLOOKUP(F3,'(参考)イベント受信待ち'!A:F,3,FALSE)) -> 該当無し | J3: =IF(ISERROR(VLOOKUP(F3,'(参考)イベント受信待ち'!A:F,4,FALSE)),"該当無し",VLOOKUP(F3,'(参考)イベント受信待ち'!A:F,4,FALSE)) -> 該当無し | M3: {=INDEX(_xlfn.TEXTSPLIT($C3,"/"),2)} -> GFOOT | N3: {=INDEX(_xlfn.TEXTSPLIT($C3,"/"),3)} -> 10_日次 | O3: {=INDEX(_xlfn.TEXTSPLIT($C3,"/"),4)} -> 01_HULFT | Q3: {=IF(ISERROR(INDEX(_xlfn.TEXTSPLIT($J3,"/"),2)),"該当なし",INDEX(_xlfn.TEXTSPLIT($J3,"/"),2))} -> 該当なし | R3: {=IF(ISERROR(INDEX(_xlfn.TEXTSPLIT($J3,"/"),3)),"該当なし",INDEX(_xlfn.TEXTSPLIT($J3,"/"),3))} -> 該当なし | S3: {=IF(ISERROR(INDEX(_xlfn.TEXTSPLIT($J3,"/"),4)),"該当なし",INDEX(_xlfn.TEXTSPLIT($J3,"/"),4))} -> 該当なし
A4: =ROW()-2 -> 2 | B4: TS_時間帯別客数更新_送_707 | C4: /GFOOT/10_日次/01_HULFT/集信_03_AEON_客数_v2 | D4: 7FFFA707 時間帯別売上速報作成ジョブへの連携 | E4: JP1イベント送信 | F4: 7FFFA707 | H4: =IF(ISERROR(VLOOKUP(F4,'(参考)イベント受信待ち'!A:F,2,FALSE)),"該当無し",VLOOKUP(F4,'(参考)イベント受信待ち'!A:F,2,FALSE)) -> 該当無し | I4: =IF(ISERROR(VLOOKUP(F4,'(参考)イベント受信待ち'!A:F,3,FALSE)),"該当無し",VLOOKUP(F4,'(参考)イベント受信待ち'!A:F,3,FALSE)) -> 該当無し | J4: =IF(ISERROR(VLOOKUP(F4,'(参考)イベント受信待ち'!A:F,4,FALSE)),"該当無し",VLOOKUP(F4,'(参考)イベント受信待ち'!A:F,4,FALSE)) -> 該当無し | M4: {=INDEX(_xlfn.TEXTSPLIT($C4,"/"),2)} -> GFOOT | N4: {=INDEX(_xlfn.TEXTSPLIT($C4,"/"),3)} -> 10_日次 | O4: {=INDEX(_xlfn.TEXTSPLIT($C4,"/"),4)} -> 01_HULFT | Q4: {=IF(ISERROR(INDEX(_xlfn.TEXTSPLIT($J4,"/"),2)),"該当なし",INDEX(_xlfn.TEXTSPLIT($J4,"/"),2))} -> 該当なし | R4: {=IF(ISERROR(INDEX(_xlfn.TEXTSPLIT($J4,"/"),3)),"該当なし",INDEX(_xlfn.TEXTSPLIT($J4,"/"),3))} -> 該当なし | S4: {=IF(ISERROR(INDEX(_xlfn.TEXTSPLIT($J4,"/"),4)),"該当なし",INDEX(_xlfn.TEXTSPLIT($J4,"/"),4))} -> 該当なし
A5: =ROW()-2 -> 3 | B5: NLOG取込完了イベント_送_706 | C5: /GFOOT/10_日次/01_HULFT/集信_05_共通POS_POS売上_NLOG | D5: 7FFFA706 | E5: JP1イベント送信 | F5: 7FFFA706 | H5: =IF(ISERROR(VLOOKUP(F5,'(参考)イベント受信待ち'!A:F,2,FALSE)),"該当無し",VLOOKUP(F5,'(参考)イベント受信待ち'!A:F,2,FALSE)) -> 32 | I5: =IF(ISERROR(VLOOKUP(F5,'(参考)イベント受信待ち'!A:F,3,FALSE)),"該当無し",VLOOKUP(F5,'(参考)イベント受信待ち'!A:F,3,FALSE)) -> NLOG受信後処理_受_706 | J5: =IF(ISERROR(VLOOKUP(F5,'(参考)イベント受信待ち'!A:F,4,FALSE)),"該当無し",VLOOKUP(F5,'(参考)イベント受信待ち'!A:F,4,FALSE)) -> /GFOOT/10_日次/10_DWH/01_NLOG受信後処理_Dr.Sum更新 | M5: {=INDEX(_xlfn.TEXTSPLIT($C5,"/"),2)} -> GFOOT | N5: {=INDEX(_xlfn.TEXTSPLIT($C5,"/"),3)} -> 10_日次 | O5: {=INDEX(_xlfn.TEXTSPLIT($C5,"/"),4)} -> 01_HULFT | Q5: {=IF(ISERROR(INDEX(_xlfn.TEXTSPLIT($J5,"/"),2)),"該当なし",INDEX(_xlfn.TEXTSPLIT($J5,"/"),2))} -> GFOOT | R5: {=IF(ISERROR(INDEX(_xlfn.TEXTSPLIT($J5,"/"),3)),"該当なし",INDEX(_xlfn.TEXTSPLIT($J5,"/"),3))} -> 10_日次 | S5: {=IF(ISERROR(INDEX(_xlfn.TEXTSPLIT($J5,"/"),4)),"該当なし",INDEX(_xlfn.TEXTSPLIT($J5,"/"),4))} -> 10_DWH
A6: =ROW()-2 -> 4 | B6: AEON単品売上データ連携終了 | C6: /GFOOT/10_日次/01_HULFT/集信_06_イオンコンセ_単品売上/終了イベント送信_7FFFA003 | D6: 7FFFA003 AEON単品売上データ連携終了 | E6: JP1イベント送信 | F6: 7FFFA003 | H6: =IF(ISERROR(VLOOKUP(F6,'(参考)イベント受信待ち'!A:F,2,FALSE)),"該当無し",VLOOKUP(F6,'(参考)イベント受信待ち'!A:F,2,FALSE)) -> 57 | I6: =IF(ISERROR(VLOOKUP(F6,'(参考)イベント受信待ち'!A:F,3,FALSE)),"該当無し",VLOOKUP(F6,'(参考)イベント受信待ち'!A:F,3,FALSE)) -> 受信確認_7FFFA003 | J6: =IF(ISERROR(VLOOKUP(F6,'(参考)イベント受信待ち'!A:F,4,FALSE)),"該当無し",VLOOKUP(F6,'(参考)イベント受信待ち'!A:F,4,FALSE)) -> /GFOOT/10_日次/N0100_02_日次/受信_売上・店舗BO・WEB申請/AEONコンセ | M6: {=INDEX(_xlfn.TEXTSPLIT($C6,"/"),2)} -> GFOOT | N6: {=INDEX(_xlfn.TEXTSPLIT($C6,"/"),3)} -> 10_日次 | O6: {=INDEX(_xlfn.TEXTSPLIT($C6,"/"),4)} -> 01_HULFT | Q6: {=IF(ISERROR(INDEX(_xlfn.TEXTSPLIT($J6,"/"),2)),"該当なし",INDEX(_xlfn.TEXTSPLIT($J6,"/"),2))} -> GFOOT | R6: {=IF(ISERROR(INDEX(_xlfn.TEXTSPLIT($J6,"/"),3)),"該当なし",INDEX(_xlfn.TEXTSPLIT($J6,"/"),3))} -> 10_日次 | S6: {=IF(ISERROR(INDEX(_xlfn.TEXTSPLIT($J6,"/"),4)),"該当なし",INDEX(_xlfn.TEXTSPLIT($J6,"/"),4))} -> N0100_02_日次
A7: =ROW()-2 -> 5 | B7: 取引先在庫_PSS投入_送_7FFFB501 | C7: /GFOOT/10_日次/01_HULFT/集信_31_PSS_004 | D7: 7FFFB501 日次処理にてイベントを受信 | E7: JP1イベント送信 | F7: 7FFFB501 | H7: =IF(ISERROR(VLOOKUP(F7,'(参考)イベント受信待ち'!A:F,2,FALSE)),"該当無し",VLOOKUP(F7,'(参考)イベント受信待ち'!A:F,2,FALSE)) -> 60 | I7: =IF(ISERROR(VLOOKUP(F7,'(参考)イベント受信待ち'!A:F,3,FALSE)),"該当無し",VLOOKUP(F7,'(参考)イベント受信待ち'!A:F,3,FALSE)) -> 発注停止再開_受信_7FFFB501 | J7: =IF(ISERROR(VLOOKUP(F7,'(参考)イベント受信待ち'!A:F,4,FALSE)),"該当無し",VLOOKUP(F7,'(参考)イベント受信待ち'!A:F,4,FALSE)) -> /GFOOT/10_日次/N0100_02_日次 | M7: {=INDEX(_xlfn.TEXTSPLIT($C7,"/"),2)} -> GFOOT | N7: {=INDEX(_xlfn.TEXTSPLIT($C7,"/"),3)} -> 10_日次 | O7: {=INDEX(_xlfn.TEXTSPLIT($C7,"/"),4)} -> 01_HULFT | Q7: {=IF(ISERROR(INDEX(_xlfn.TEXTSPLIT($J7,"/"),2)),"該当なし",INDEX(_xlfn.TEXTSPLIT($J7,"/"),2))} -> GFOOT | R7: {=IF(ISERROR(INDEX(_xlfn.TEXTSPLIT($J7,"/"),3)),"該当なし",INDEX(_xlfn.TEXTSPLIT($J7,"/"),3))} -> 10_日次 | S7: {=IF(ISERROR(INDEX(_xlfn.TEXTSPLIT($J7,"/"),4)),"該当なし",INDEX(_xlfn.TEXTSPLIT($J7,"/"),4))} -> N0100_02_日次
A8: =ROW()-2 -> 6 | B8: ANPLU_作成完了_7FFFA512 | C8: /GFOOT/10_日次/01_HULFT/配信_11_AEON_商品マスタ | D8: 7FFFA512_AEON_商品マスタ送信完了_ANPLU | E8: JP1イベント送信 | F8: 7FFFA512 | H8: =IF(ISERROR(VLOOKUP(F8,'(参考)イベント受信待ち'!A:F,2,FALSE)),"該当無し",VLOOKUP(F8,'(参考)イベント受信待ち'!A:F,2,FALSE)) -> 61 | I8: =IF(ISERROR(VLOOKUP(F8,'(参考)イベント受信待ち'!A:F,3,FALSE)),"該当無し",VLOOKUP(F8,'(参考)イベント受信待ち'!A:F,3,FALSE)) -> ANPLU_作成完了_7FFFA512 | J8: =IF(ISERROR(VLOOKUP(F8,'(参考)イベント受信待ち'!A:F,4,FALSE)),"該当無し",VLOOKUP(F8,'(参考)イベント受信待ち'!A:F,4,FALSE)) -> /GFOOT/10_日次/N2910_日次監視 | M8: {=INDEX(_xlfn.TEXTSPLIT($C8,"/"),2)} -> GFOOT | N8: {=INDEX(_xlfn.TEXTSPLIT($C8,"/"),3)} -> 10_日次 | O8: {=INDEX(_xlfn.TEXTSPLIT($C8,"/"),4)} -> 01_HULFT | Q8: {=IF(ISERROR(INDEX(_xlfn.TEXTSPLIT($J8,"/"),2)),"該当なし",INDEX(_xlfn.TEXTSPLIT($J8,"/"),2))} -> GFOOT | R8: {=IF(ISERROR(INDEX(_xlfn.TEXTSPLIT($J8,"/"),3)),"該当なし",INDEX(_xlfn.TEXTSPLIT($J8,"/"),3))} -> 10_日次 | S8: {=IF(ISERROR(INDEX(_xlfn.TEXTSPLIT($J8,"/"),4)),"該当なし",INDEX(_xlfn.TEXTSPLIT($J8,"/"),4))} -> N2910_日次監視
A9: =ROW()-2 -> 7 | B9: ANPLU_送信完了_7FFFA513 | C9: /GFOOT/10_日次/01_HULFT/配信_11_AEON_商品マスタ | D9: 7FFFA513_AEON_商品マスタ送信完了 | E9: JP1イベント送信 | F9: 7FFFA513 | H9: =IF(ISERROR(VLOOKUP(F9,'(参考)イベント受信待ち'!A:F,2,FALSE)),"該当無し",VLOOKUP(F9,'(参考)イベント受信待ち'!A:F,2,FALSE)) -> 62 | I9: =IF(ISERROR(VLOOKUP(F9,'(参考)イベント受信待ち'!A:F,3,FALSE)),"該当無し",VLOOKUP(F9,'(参考)イベント受信待ち'!A:F,3,FALSE)) -> ANPLU_作成完了_7FFFA513 | J9: =IF(ISERROR(VLOOKUP(F9,'(参考)イベント受信待ち'!A:F,4,FALSE)),"該当無し",VLOOKUP(F9,'(参考)イベント受信待ち'!A:F,4,FALSE)) -> /GFOOT/10_日次/N2910_日次監視 | M9: {=INDEX(_xlfn.TEXTSPLIT($C9,"/"),2)} -> GFOOT | N9: {=INDEX(_xlfn.TEXTSPLIT($C9,"/"),3)} -> 10_日次 | O9: {=INDEX(_xlfn.TEXTSPLIT($C9,"/"),4)} -> 01_HULFT | Q9: {=IF(ISERROR(INDEX(_xlfn.TEXTSPLIT($J9,"/"),2)),"該当なし",INDEX(_xlfn.TEXTSPLIT($J9,"/"),2))} -> GFOOT | R9: {=IF(ISERROR(INDEX(_xlfn.TEXTSPLIT($J9,"/"),3)),"該当なし",INDEX(_xlfn.TEXTSPLIT($J9,"/"),3))} -> 10_日次 | S9: {=IF(ISERROR(INDEX(_xlfn.TEXTSPLIT($J9,"/"),4)),"該当なし",INDEX(_xlfn.TEXTSPLIT($J9,"/"),4))} -> N2910_日次監視
A10: =ROW()-2 -> 8 | B10: 送710_ASMVAHSEND_HULFT | C10: /GFOOT/10_日次/01_HULFT/配信_33_ASM向け_発注検収返品デ | D10: 7FFFA710 送信完了イベント | E10: JP1イベント送信 | F10: 7FFFA710 | H10: =IF(ISERROR(VLOOKUP(F10,'(参考)イベント受信待ち'!A:F,2,FALSE)),"該当無し",VLOOKUP(F10,'(参考)イベント受信待ち'!A:F,2,FALSE)) -> 64 | I10: =IF(ISERROR(VLOOKUP(F10,'(参考)イベント受信待ち'!A:F,3,FALSE)),"該当無し",VLOOKUP(F10,'(参考)イベント受信待ち'!A:F,3,FALSE)) -> ASM発注検収返品データ_7FFFA710 | J10: =IF(ISERROR(VLOOKUP(F10,'(参考)イベント受信待ち'!A:F,4,FALSE)),"該当無し",VLOOKUP(F10,'(参考)イベント受信待ち'!A:F,4,FALSE)) -> /GFOOT/10_日次/N2910_日次監視 | M10: {=INDEX(_xlfn.TEXTSPLIT($C10,"/"),2)} -> GFOOT | N10: {=INDEX(_xlfn.TEXTSPLIT($C10,"/"),3)} -> 10_日次 | O10: {=INDEX(_xlfn.TEXTSPLIT($C10,"/"),4)} -> 01_HULFT | Q10: {=IF(ISERROR(INDEX(_xlfn.TEXTSPLIT($J10,"/"),2)),"該当なし",INDEX(_xlfn.TEXTSPLIT($J10,"/"),2))} -> GFOOT | R10: {=IF(ISERROR(INDEX(_xlfn.TEXTSPLIT($J10,"/"),3)),"該当なし",INDEX(_xlfn.TEXTSPLIT($J10,"/"),3))} -> 10_日次 | S10: {=IF(ISERROR(INDEX(_xlfn.TEXTSPLIT($J10,"/"),4)),"該当なし",INDEX(_xlfn.TEXTSPLIT($J10,"/"),4))} -> N2910_日次監視
A11: =ROW()-2 -> 9 | B11: JP1イベント送信 | C11: /GFOOT/10_日次/03_EC/020_EC_データ受信 | D11: 7FFFA501 EC_comデータ受信完了 | E11: JP1イベント送信 | F11: 7FFFA501 | H11: =IF(ISERROR(VLOOKUP(F11,'(参考)イベント受信待ち'!A:F,2,FALSE)),"該当無し",VLOOKUP(F11,'(参考)イベント受信待ち'!A:F,2,FALSE)) -> 59 | I11: =IF(ISERROR(VLOOKUP(F11,'(参考)イベント受信待ち'!A:F,3,FALSE)),"該当無し",VLOOKUP(F11,'(参考)イベント受信待ち'!A:F,3,FALSE)) -> EC_COM受信完了_7FFFA501 | J11: =IF(ISERROR(VLOOKUP(F11,'(参考)イベント受信待ち'!A:F,4,FALSE)),"該当無し",VLOOKUP(F11,'(参考)イベント受信待ち'!A:F,4,FALSE)) -> /GFOOT/10_日次/N0100_02_日次/受信_売上・店舗BO・WEB申請/EC | M11: {=INDEX(_xlfn.TEXTSPLIT($C11,"/"),2)} -> GFOOT | N11: {=INDEX(_xlfn.TEXTSPLIT($C11,"/"),3)} -> 10_日次 | O11: {=INDEX(_xlfn.TEXTSPLIT($C11,"/"),4)} -> 03_EC | Q11: {=IF(ISERROR(INDEX(_xlfn.TEXTSPLIT($J11,"/"),2)),"該当なし",INDEX(_xlfn.TEXTSPLIT($J11,"/"),2))} -> GFOOT | R11: {=IF(ISERROR(INDEX(_xlfn.TEXTSPLIT($J11,"/"),3)),"該当なし",INDEX(_xlfn.TEXTSPLIT($J11,"/"),3))} -> 10_日次 | S11: {=IF(ISERROR(INDEX(_xlfn.TEXTSPLIT($J11,"/"),4)),"該当なし",INDEX(_xlfn.TEXTSPLIT($J11,"/"),4))} -> N0100_02_日次
A12: =ROW()-2 -> 10 | B12: INTR_T作成完了 | C12: /GFOOT/10_日次/05_棚卸/棚卸データ受信_v2.0 | D12: 7FFFA533 INTR_T作成完了 | E12: JP1イベント送信 | F12: 7FFFA533 | H12: =IF(ISERROR(VLOOKUP(F12,'(参考)イベント受信待ち'!A:F,2,FALSE)),"該当無し",VLOOKUP(F12,'(参考)イベント受信待ち'!A:F,2,FALSE)) -> 42 | I12: =IF(ISERROR(VLOOKUP(F12,'(参考)イベント受信待ち'!A:F,3,FALSE)),"該当無し",VLOOKUP(F12,'(参考)イベント受信待ち'!A:F,3,FALSE)) -> INTR_T作成完了 | J12: =IF(ISERROR(VLOOKUP(F12,'(参考)イベント受信待ち'!A:F,4,FALSE)),"該当無し",VLOOKUP(F12,'(参考)イベント受信待ち'!A:F,4,FALSE)) -> /GFOOT/10_日次/10_NAIS/11_NAIS_実績データ送信 | M12: {=INDEX(_xlfn.TEXTSPLIT($C12,"/"),2)} -> GFOOT | N12: {=INDEX(_xlfn.TEXTSPLIT($C12,"/"),3)} -> 10_日次 | O12: {=INDEX(_xlfn.TEXTSPLIT($C12,"/"),4)} -> 05_棚卸 | Q12: {=IF(ISERROR(INDEX(_xlfn.TEXTSPLIT($J12,"/"),2)),"該当なし",INDEX(_xlfn.TEXTSPLIT($J12,"/"),2))} -> GFOOT | R12: {=IF(ISERROR(INDEX(_xlfn.TEXTSPLIT($J12,"/"),3)),"該当なし",INDEX(_xlfn.TEXTSPLIT($J12,"/"),3))} -> 10_日次 | S12: {=IF(ISERROR(INDEX(_xlfn.TEXTSPLIT($J12,"/"),4)),"該当なし",INDEX(_xlfn.TEXTSPLIT($J12,"/"),4))} -> 10_NAIS
A13: =ROW()-2 -> 11 | B13: 発注データ受信_送583 | C13: /GFOOT/10_日次/08_商品供給/11_商品供給_発注データ受信/BMSHAC受信リトライ | D13: 583 17時リトライ完了 | E13: JP1イベント送信 | F13: 583 | H13: =IF(ISERROR(VLOOKUP(F13,'(参考)イベント受信待ち'!A:F,2,FALSE)),"該当無し",VLOOKUP(F13,'(参考)イベント受信待ち'!A:F,2,FALSE)) -> 27 | I13: =IF(ISERROR(VLOOKUP(F13,'(参考)イベント受信待ち'!A:F,3,FALSE)),"該当無し",VLOOKUP(F13,'(参考)イベント受信待ち'!A:F,3,FALSE)) -> 発注データ受信_受583 | J13: =IF(ISERROR(VLOOKUP(F13,'(参考)イベント受信待ち'!A:F,4,FALSE)),"該当無し",VLOOKUP(F13,'(参考)イベント受信待ち'!A:F,4,FALSE)) -> /GFOOT/10_日次/08_商品供給/11_商品供給_発注データ受信 | M13: {=INDEX(_xlfn.TEXTSPLIT($C13,"/"),2)} -> GFOOT | N13: {=INDEX(_xlfn.TEXTSPLIT($C13,"/"),3)} -> 10_日次 | O13: {=INDEX(_xlfn.TEXTSPLIT($C13,"/"),4)} -> 08_商品供給 | Q13: {=IF(ISERROR(INDEX(_xlfn.TEXTSPLIT($J13,"/"),2)),"該当なし",INDEX(_xlfn.TEXTSPLIT($J13,"/"),2))} -> GFOOT | R13: {=IF(ISERROR(INDEX(_xlfn.TEXTSPLIT($J13,"/"),3)),"該当なし",INDEX(_xlfn.TEXTSPLIT($J13,"/"),3))} -> 10_日次 | S13: {=IF(ISERROR(INDEX(_xlfn.TEXTSPLIT($J13,"/"),4)),"該当なし",INDEX(_xlfn.TEXTSPLIT($J13,"/"),4))} -> 08_商品供給
A14: =ROW()-2 -> 12 | B14: 受領データ受信_送584 | C14: /GFOOT/10_日次/08_商品供給/11_商品供給_発注データ受信/BMSJYU受信リトライ | D14: 584 17時リトライ完了 | E14: JP1イベント送信 | F14: 584 | H14: =IF(ISERROR(VLOOKUP(F14,'(参考)イベント受信待ち'!A:F,2,FALSE)),"該当無し",VLOOKUP(F14,'(参考)イベント受信待ち'!A:F,2,FALSE)) -> 26 | I14: =IF(ISERROR(VLOOKUP(F14,'(参考)イベント受信待ち'!A:F,3,FALSE)),"該当無し",VLOOKUP(F14,'(参考)イベント受信待ち'!A:F,3,FALSE)) -> 受領データ受信_受584 | J14: =IF(ISERROR(VLOOKUP(F14,'(参考)イベント受信待ち'!A:F,4,FALSE)),"該当無し",VLOOKUP(F14,'(参考)イベント受信待ち'!A:F,4,FALSE)) -> /GFOOT/10_日次/08_商品供給/11_商品供給_発注データ受信 | M14: {=INDEX(_xlfn.TEXTSPLIT($C14,"/"),2)} -> GFOOT | N14: {=INDEX(_xlfn.TEXTSPLIT($C14,"/"),3)} -> 10_日次 | O14: {=INDEX(_xlfn.TEXTSPLIT($C14,"/"),4)} -> 08_商品供給 | Q14: {=IF(ISERROR(INDEX(_xlfn.TEXTSPLIT($J14,"/"),2)),"該当なし",INDEX(_xlfn.TEXTSPLIT($J14,"/"),2))} -> GFOOT | R14: {=IF(ISERROR(INDEX(_xlfn.TEXTSPLIT($J14,"/"),3)),"該当なし",INDEX(_xlfn.TEXTSPLIT($J14,"/"),3))} -> 10_日次 | S14: {=IF(ISERROR(INDEX(_xlfn.TEXTSPLIT($J14,"/"),4)),"該当なし",INDEX(_xlfn.TEXTSPLIT($J14,"/"),4))} -> 08_商品供給
A15: =ROW()-2 -> 13 | B15: 受領データ受信_送584 | C15: /GFOOT/10_日次/08_商品供給/11_商品供給_発注データ受信 | D15: 584 ファイルサイズが0以外 | E15: JP1イベント送信 | F15: 584 | H15: =IF(ISERROR(VLOOKUP(F15,'(参考)イベント受信待ち'!A:F,2,FALSE)),"該当無し",VLOOKUP(F15,'(参考)イベント受信待ち'!A:F,2,FALSE)) -> 26 | I15: =IF(ISERROR(VLOOKUP(F15,'(参考)イベント受信待ち'!A:F,3,FALSE)),"該当無し",VLOOKUP(F15,'(参考)イベント受信待ち'!A:F,3,FALSE)) -> 受領データ受信_受584 | J15: =IF(ISERROR(VLOOKUP(F15,'(参考)イベント受信待ち'!A:F,4,FALSE)),"該当無し",VLOOKUP(F15,'(参考)イベント受信待ち'!A:F,4,FALSE)) -> /GFOOT/10_日次/08_商品供給/11_商品供給_発注データ受信 | M15: {=INDEX(_xlfn.TEXTSPLIT($C15,"/"),2)} -> GFOOT | N15: {=INDEX(_xlfn.TEXTSPLIT($C15,"/"),3)} -> 10_日次 | O15: {=INDEX(_xlfn.TEXTSPLIT($C15,"/"),4)} -> 08_商品供給 | Q15: {=IF(ISERROR(INDEX(_xlfn.TEXTSPLIT($J15,"/"),2)),"該当なし",INDEX(_xlfn.TEXTSPLIT($J15,"/"),2))} -> GFOOT | R15: {=IF(ISERROR(INDEX(_xlfn.TEXTSPLIT($J15,"/"),3)),"該当なし",INDEX(_xlfn.TEXTSPLIT($J15,"/"),3))} -> 10_日次 | S15: {=IF(ISERROR(INDEX(_xlfn.TEXTSPLIT($J15,"/"),4)),"該当なし",INDEX(_xlfn.TEXTSPLIT($J15,"/"),4))} -> 08_商品供給
A16: =ROW()-2 -> 14 | B16: 発注データ受信_送583 | C16: /GFOOT/10_日次/08_商品供給/11_商品供給_発注データ受信 | D16: 583 ファイルサイズが0以外 | E16: JP1イベント送信 | F16: 583 | H16: =IF(ISERROR(VLOOKUP(F16,'(参考)イベント受信待ち'!A:F,2,FALSE)),"該当無し",VLOOKUP(F16,'(参考)イベント受信待ち'!A:F,2,FALSE)) -> 27 | I16: =IF(ISERROR(VLOOKUP(F16,'(参考)イベント受信待ち'!A:F,3,FALSE)),"該当無し",VLOOKUP(F16,'(参考)イベント受信待ち'!A:F,3,FALSE)) -> 発注データ受信_受583 | J16: =IF(ISERROR(VLOOKUP(F16,'(参考)イベント受信待ち'!A:F,4,FALSE)),"該当無し",VLOOKUP(F16,'(参考)イベント受信待ち'!A:F,4,FALSE)) -> /GFOOT/10_日次/08_商品供給/11_商品供給_発注データ受信 | M16: {=INDEX(_xlfn.TEXTSPLIT($C16,"/"),2)} -> GFOOT | N16: {=INDEX(_xlfn.TEXTSPLIT($C16,"/"),3)} -> 10_日次 | O16: {=INDEX(_xlfn.TEXTSPLIT($C16,"/"),4)} -> 08_商品供給 | Q16: {=IF(ISERROR(INDEX(_xlfn.TEXTSPLIT($J16,"/"),2)),"該当なし",INDEX(_xlfn.TEXTSPLIT($J16,"/"),2))} -> GFOOT | R16: {=IF(ISERROR(INDEX(_xlfn.TEXTSPLIT($J16,"/"),3)),"該当なし",INDEX(_xlfn.TEXTSPLIT($J16,"/"),3))} -> 10_日次 | S16: {=IF(ISERROR(INDEX(_xlfn.TEXTSPLIT($J16,"/"),4)),"該当なし",INDEX(_xlfn.TEXTSPLIT($J16,"/"),4))} -> 08_商品供給
A17: =ROW()-2 -> 15 | B17: TS_時間帯別客数更新_送_707 | C17: /GFOOT/10_日次/10_DWH/01_NLOG受信後処理_Dr.Sum更新 | D17: 7FFFA707 TS_時間帯別客数更新_送_7FFFA707 | E17: JP1イベント送信 | F17: 7FFFA707 | H17: =IF(ISERROR(VLOOKUP(F17,'(参考)イベント受信待ち'!A:F,2,FALSE)),"該当無し",VLOOKUP(F17,'(参考)イベント受信待ち'!A:F,2,FALSE)) -> 該当無し | I17: =IF(ISERROR(VLOOKUP(F17,'(参考)イベント受信待ち'!A:F,3,FALSE)),"該当無し",VLOOKUP(F17,'(参考)イベント受信待ち'!A:F,3,FALSE)) -> 該当無し | J17: =IF(ISERROR(VLOOKUP(F17,'(参考)イベント受信待ち'!A:F,4,FALSE)),"該当無し",VLOOKUP(F17,'(参考)イベント受信待ち'!A:F,4,FALSE)) -> 該当無し | M17: {=INDEX(_xlfn.TEXTSPLIT($C17,"/"),2)} -> GFOOT | N17: {=INDEX(_xlfn.TEXTSPLIT($C17,"/"),3)} -> 10_日次 | O17: {=INDEX(_xlfn.TEXTSPLIT($C17,"/"),4)} -> 10_DWH | Q17: {=IF(ISERROR(INDEX(_xlfn.TEXTSPLIT($J17,"/"),2)),"該当なし",INDEX(_xlfn.TEXTSPLIT($J17,"/"),2))} -> 該当なし | R17: {=IF(ISERROR(INDEX(_xlfn.TEXTSPLIT($J17,"/"),3)),"該当なし",INDEX(_xlfn.TEXTSPLIT($J17,"/"),3))} -> 該当なし | S17: {=IF(ISERROR(INDEX(_xlfn.TEXTSPLIT($J17,"/"),4)),"該当なし",INDEX(_xlfn.TEXTSPLIT($J17,"/"),4))} -> 該当なし
A18: =ROW()-2 -> 16 | B18: 商品マスタ更新完了7FFFA702 | C18: /GFOOT/10_日次/10_DWH/10_マスタ更新 | D18: 7FFFA702 イベント送信(商品マスタ更新処理完了) | E18: JP1イベント送信 | F18: 7FFFA702 | H18: =IF(ISERROR(VLOOKUP(F18,'(参考)イベント受信待ち'!A:F,2,FALSE)),"該当無し",VLOOKUP(F18,'(参考)イベント受信待ち'!A:F,2,FALSE)) -> 12 | I18: =IF(ISERROR(VLOOKUP(F18,'(参考)イベント受信待ち'!A:F,3,FALSE)),"該当無し",VLOOKUP(F18,'(参考)イベント受信待ち'!A:F,3,FALSE)) -> 商品ＲＭ更新処理完了_702 | J18: =IF(ISERROR(VLOOKUP(F18,'(参考)イベント受信待ち'!A:F,4,FALSE)),"該当無し",VLOOKUP(F18,'(参考)イベント受信待ち'!A:F,4,FALSE)) -> /GFOOT/10_日次/01_HULFT/配信_34_LOMOS_自動値札貼付 | M18: {=INDEX(_xlfn.TEXTSPLIT($C18,"/"),2)} -> GFOOT | N18: {=INDEX(_xlfn.TEXTSPLIT($C18,"/"),3)} -> 10_日次 | O18: {=INDEX(_xlfn.TEXTSPLIT($C18,"/"),4)} -> 10_DWH | Q18: {=IF(ISERROR(INDEX(_xlfn.TEXTSPLIT($J18,"/"),2)),"該当なし",INDEX(_xlfn.TEXTSPLIT($J18,"/"),2))} -> GFOOT | R18: {=IF(ISERROR(INDEX(_xlfn.TEXTSPLIT($J18,"/"),3)),"該当なし",INDEX(_xlfn.TEXTSPLIT($J18,"/"),3))} -> 10_日次 | S18: {=IF(ISERROR(INDEX(_xlfn.TEXTSPLIT($J18,"/"),4)),"該当なし",INDEX(_xlfn.TEXTSPLIT($J18,"/"),4))} -> 01_HULFT
A19: =ROW()-2 -> 17 | B19: 店舗売価マスタ_BO転送_完了 | C19: /GFOOT/10_日次/10_DWH/12_店舗売価マスタ更新_BO転入 | D19: 7FFFA708 店舗売価マスタ_BO転送_完了 | E19: JP1イベント送信 | F19: 7FFFA708 | H19: =IF(ISERROR(VLOOKUP(F19,'(参考)イベント受信待ち'!A:F,2,FALSE)),"該当無し",VLOOKUP(F19,'(参考)イベント受信待ち'!A:F,2,FALSE)) -> 2 | I19: =IF(ISERROR(VLOOKUP(F19,'(参考)イベント受信待ち'!A:F,3,FALSE)),"該当無し",VLOOKUP(F19,'(参考)イベント受信待ち'!A:F,3,FALSE)) -> 店舗売価マスタ_BO転入完了 | J19: =IF(ISERROR(VLOOKUP(F19,'(参考)イベント受信待ち'!A:F,4,FALSE)),"該当無し",VLOOKUP(F19,'(参考)イベント受信待ち'!A:F,4,FALSE)) -> /GFOOT/10_日次/01_HULFT/配信_11_AEON_商品マスタ | M19: {=INDEX(_xlfn.TEXTSPLIT($C19,"/"),2)} -> GFOOT | N19: {=INDEX(_xlfn.TEXTSPLIT($C19,"/"),3)} -> 10_日次 | O19: {=INDEX(_xlfn.TEXTSPLIT($C19,"/"),4)} -> 10_DWH | Q19: {=IF(ISERROR(INDEX(_xlfn.TEXTSPLIT($J19,"/"),2)),"該当なし",INDEX(_xlfn.TEXTSPLIT($J19,"/"),2))} -> GFOOT | R19: {=IF(ISERROR(INDEX(_xlfn.TEXTSPLIT($J19,"/"),3)),"該当なし",INDEX(_xlfn.TEXTSPLIT($J19,"/"),3))} -> 10_日次 | S19: {=IF(ISERROR(INDEX(_xlfn.TEXTSPLIT($J19,"/"),4)),"該当なし",INDEX(_xlfn.TEXTSPLIT($J19,"/"),4))} -> 01_HULFT
A20: =ROW()-2 -> 18 | B20: 週別店別単品実績更新終了 | C20: /GFOOT/10_日次/10_DWH/15_DWH_Dr.Sum更新 | D20: 7FFFA705 /20_週次/EXCELデータ作成/W03_データ作成 にて使用 | E20: JP1イベント送信 | F20: 7FFFA705 | H20: =IF(ISERROR(VLOOKUP(F20,'(参考)イベント受信待ち'!A:F,2,FALSE)),"該当無し",VLOOKUP(F20,'(参考)イベント受信待ち'!A:F,2,FALSE)) -> 39 | I20: =IF(ISERROR(VLOOKUP(F20,'(参考)イベント受信待ち'!A:F,3,FALSE)),"該当無し",VLOOKUP(F20,'(参考)イベント受信待ち'!A:F,3,FALSE)) -> 週別店別単品実績更新終了 | J20: =IF(ISERROR(VLOOKUP(F20,'(参考)イベント受信待ち'!A:F,4,FALSE)),"該当無し",VLOOKUP(F20,'(参考)イベント受信待ち'!A:F,4,FALSE)) -> /GFOOT/10_日次/10_DWH/21_週別_DrSum_レポート更新 | M20: {=INDEX(_xlfn.TEXTSPLIT($C20,"/"),2)} -> GFOOT | N20: {=INDEX(_xlfn.TEXTSPLIT($C20,"/"),3)} -> 10_日次 | O20: {=INDEX(_xlfn.TEXTSPLIT($C20,"/"),4)} -> 10_DWH | Q20: {=IF(ISERROR(INDEX(_xlfn.TEXTSPLIT($J20,"/"),2)),"該当なし",INDEX(_xlfn.TEXTSPLIT($J20,"/"),2))} -> GFOOT | R20: {=IF(ISERROR(INDEX(_xlfn.TEXTSPLIT($J20,"/"),3)),"該当なし",INDEX(_xlfn.TEXTSPLIT($J20,"/"),3))} -> 10_日次 | S20: {=IF(ISERROR(INDEX(_xlfn.TEXTSPLIT($J20,"/"),4)),"該当なし",INDEX(_xlfn.TEXTSPLIT($J20,"/"),4))} -> 10_DWH
A21: =ROW()-2 -> 19 | B21: 送1701_APV->ADW取込終了 | C21: /GFOOT/10_日次/10_DWH/15_DWH_Dr.Sum更新 | D21: 7FFFA701 APV->DWH取込処理終了イベント送信 | E21: JP1イベント送信 | F21: 7FFFA701 | H21: =IF(ISERROR(VLOOKUP(F21,'(参考)イベント受信待ち'!A:F,2,FALSE)),"該当無し",VLOOKUP(F21,'(参考)イベント受信待ち'!A:F,2,FALSE)) -> 14 | I21: =IF(ISERROR(VLOOKUP(F21,'(参考)イベント受信待ち'!A:F,3,FALSE)),"該当無し",VLOOKUP(F21,'(参考)イベント受信待ち'!A:F,3,FALSE)) -> APV->DWH取込処理終了_7FFFA701 | J21: =IF(ISERROR(VLOOKUP(F21,'(参考)イベント受信待ち'!A:F,4,FALSE)),"該当無し",VLOOKUP(F21,'(参考)イベント受信待ち'!A:F,4,FALSE)) -> /GFOOT/10_日次/01_HULFT/配信_50_AEON_経営DB | M21: {=INDEX(_xlfn.TEXTSPLIT($C21,"/"),2)} -> GFOOT | N21: {=INDEX(_xlfn.TEXTSPLIT($C21,"/"),3)} -> 10_日次 | O21: {=INDEX(_xlfn.TEXTSPLIT($C21,"/"),4)} -> 10_DWH | Q21: {=IF(ISERROR(INDEX(_xlfn.TEXTSPLIT($J21,"/"),2)),"該当なし",INDEX(_xlfn.TEXTSPLIT($J21,"/"),2))} -> GFOOT | R21: {=IF(ISERROR(INDEX(_xlfn.TEXTSPLIT($J21,"/"),3)),"該当なし",INDEX(_xlfn.TEXTSPLIT($J21,"/"),3))} -> 10_日次 | S21: {=IF(ISERROR(INDEX(_xlfn.TEXTSPLIT($J21,"/"),4)),"該当なし",INDEX(_xlfn.TEXTSPLIT($J21,"/"),4))} -> 01_HULFT
A22: =ROW()-2 -> 20 | B22: 送703_店舗売価マスタ更新処理 | C22: /GFOOT/10_日次/10_DWH/15_DWH_Dr.Sum更新 | D22: 7FFFA703_店舗売価マスタ更新処理終了 | E22: JP1イベント送信 | F22: 7FFFA703 | H22: =IF(ISERROR(VLOOKUP(F22,'(参考)イベント受信待ち'!A:F,2,FALSE)),"該当無し",VLOOKUP(F22,'(参考)イベント受信待ち'!A:F,2,FALSE)) -> 24 | I22: =IF(ISERROR(VLOOKUP(F22,'(参考)イベント受信待ち'!A:F,3,FALSE)),"該当無し",VLOOKUP(F22,'(参考)イベント受信待ち'!A:F,3,FALSE)) -> 店舗売価マスタ更新：703 | J22: =IF(ISERROR(VLOOKUP(F22,'(参考)イベント受信待ち'!A:F,4,FALSE)),"該当無し",VLOOKUP(F22,'(参考)イベント受信待ち'!A:F,4,FALSE)) -> /GFOOT/10_日次/05_棚卸/商品マスタ送信_v2.0 | M22: {=INDEX(_xlfn.TEXTSPLIT($C22,"/"),2)} -> GFOOT | N22: {=INDEX(_xlfn.TEXTSPLIT($C22,"/"),3)} -> 10_日次 | O22: {=INDEX(_xlfn.TEXTSPLIT($C22,"/"),4)} -> 10_DWH | Q22: {=IF(ISERROR(INDEX(_xlfn.TEXTSPLIT($J22,"/"),2)),"該当なし",INDEX(_xlfn.TEXTSPLIT($J22,"/"),2))} -> GFOOT | R22: {=IF(ISERROR(INDEX(_xlfn.TEXTSPLIT($J22,"/"),3)),"該当なし",INDEX(_xlfn.TEXTSPLIT($J22,"/"),3))} -> 10_日次 | S22: {=IF(ISERROR(INDEX(_xlfn.TEXTSPLIT($J22,"/"),4)),"該当なし",INDEX(_xlfn.TEXTSPLIT($J22,"/"),4))} -> 05_棚卸
A23: =ROW()-2 -> 21 | B23: 社員現職情報更新完了 | C23: /GFOOT/10_日次/30_人事関連/02_ADPSデータLoad_ADW_V2 | D23: 7FFFA770 社員現職情報更新完了 | E23: JP1イベント送信 | F23: 7FFFA770 | H23: =IF(ISERROR(VLOOKUP(F23,'(参考)イベント受信待ち'!A:F,2,FALSE)),"該当無し",VLOOKUP(F23,'(参考)イベント受信待ち'!A:F,2,FALSE)) -> 47 | I23: =IF(ISERROR(VLOOKUP(F23,'(参考)イベント受信待ち'!A:F,3,FALSE)),"該当無し",VLOOKUP(F23,'(参考)イベント受信待ち'!A:F,3,FALSE)) -> 社員現職情報更新完了 | J23: =IF(ISERROR(VLOOKUP(F23,'(参考)イベント受信待ち'!A:F,4,FALSE)),"該当無し",VLOOKUP(F23,'(参考)イベント受信待ち'!A:F,4,FALSE)) -> /GFOOT/10_日次/30_人事関連/03_社員・組織情報作成 | M23: {=INDEX(_xlfn.TEXTSPLIT($C23,"/"),2)} -> GFOOT | N23: {=INDEX(_xlfn.TEXTSPLIT($C23,"/"),3)} -> 10_日次 | O23: {=INDEX(_xlfn.TEXTSPLIT($C23,"/"),4)} -> 30_人事関連 | Q23: {=IF(ISERROR(INDEX(_xlfn.TEXTSPLIT($J23,"/"),2)),"該当なし",INDEX(_xlfn.TEXTSPLIT($J23,"/"),2))} -> GFOOT | R23: {=IF(ISERROR(INDEX(_xlfn.TEXTSPLIT($J23,"/"),3)),"該当なし",INDEX(_xlfn.TEXTSPLIT($J23,"/"),3))} -> 10_日次 | S23: {=IF(ISERROR(INDEX(_xlfn.TEXTSPLIT($J23,"/"),4)),"該当なし",INDEX(_xlfn.TEXTSPLIT($J23,"/"),4))} -> 30_人事関連
A24: =ROW()-2 -> 22 | B24: JINJI共通マスタ作成完了 | C24: /GFOOT/10_日次/30_人事関連/03_社員・組織情報作成 | D24: 7FFFA771 JINJI共通マスタ作成完了 | E24: JP1イベント送信 | F24: 7FFFA771 | H24: =IF(ISERROR(VLOOKUP(F24,'(参考)イベント受信待ち'!A:F,2,FALSE)),"該当無し",VLOOKUP(F24,'(参考)イベント受信待ち'!A:F,2,FALSE)) -> 46 | I24: =IF(ISERROR(VLOOKUP(F24,'(参考)イベント受信待ち'!A:F,3,FALSE)),"該当無し",VLOOKUP(F24,'(参考)イベント受信待ち'!A:F,3,FALSE)) -> 受_771_ADPS会計データ作成完了 | J24: =IF(ISERROR(VLOOKUP(F24,'(参考)イベント受信待ち'!A:F,4,FALSE)),"該当無し",VLOOKUP(F24,'(参考)イベント受信待ち'!A:F,4,FALSE)) -> /GFOOT/10_日次/20_会計関連/40.楽楽精算向け_データ連携 | M24: {=INDEX(_xlfn.TEXTSPLIT($C24,"/"),2)} -> GFOOT | N24: {=INDEX(_xlfn.TEXTSPLIT($C24,"/"),3)} -> 10_日次 | O24: {=INDEX(_xlfn.TEXTSPLIT($C24,"/"),4)} -> 30_人事関連 | Q24: {=IF(ISERROR(INDEX(_xlfn.TEXTSPLIT($J24,"/"),2)),"該当なし",INDEX(_xlfn.TEXTSPLIT($J24,"/"),2))} -> GFOOT | R24: {=IF(ISERROR(INDEX(_xlfn.TEXTSPLIT($J24,"/"),3)),"該当なし",INDEX(_xlfn.TEXTSPLIT($J24,"/"),3))} -> 10_日次 | S24: {=IF(ISERROR(INDEX(_xlfn.TEXTSPLIT($J24,"/"),4)),"該当なし",INDEX(_xlfn.TEXTSPLIT($J24,"/"),4))} -> 20_会計関連
A25: =ROW()-2 -> 23 | B25: JP1イベント送信_7FFFA709 | C25: /GFOOT/10_日次/31_店舗/01_自動売変 | D25: 7FFFA709 売変データ更新完了 | E25: JP1イベント送信 | F25: 7FFFA709 | H25: =IF(ISERROR(VLOOKUP(F25,'(参考)イベント受信待ち'!A:F,2,FALSE)),"該当無し",VLOOKUP(F25,'(参考)イベント受信待ち'!A:F,2,FALSE)) -> 3 | I25: =IF(ISERROR(VLOOKUP(F25,'(参考)イベント受信待ち'!A:F,3,FALSE)),"該当無し",VLOOKUP(F25,'(参考)イベント受信待ち'!A:F,3,FALSE)) -> 売変データ更新完了 | J25: =IF(ISERROR(VLOOKUP(F25,'(参考)イベント受信待ち'!A:F,4,FALSE)),"該当無し",VLOOKUP(F25,'(参考)イベント受信待ち'!A:F,4,FALSE)) -> /GFOOT/10_日次/01_HULFT/配信_11_AEON_商品マスタ | M25: {=INDEX(_xlfn.TEXTSPLIT($C25,"/"),2)} -> GFOOT | N25: {=INDEX(_xlfn.TEXTSPLIT($C25,"/"),3)} -> 10_日次 | O25: {=INDEX(_xlfn.TEXTSPLIT($C25,"/"),4)} -> 31_店舗 | Q25: {=IF(ISERROR(INDEX(_xlfn.TEXTSPLIT($J25,"/"),2)),"該当なし",INDEX(_xlfn.TEXTSPLIT($J25,"/"),2))} -> GFOOT | R25: {=IF(ISERROR(INDEX(_xlfn.TEXTSPLIT($J25,"/"),3)),"該当なし",INDEX(_xlfn.TEXTSPLIT($J25,"/"),3))} -> 10_日次 | S25: {=IF(ISERROR(INDEX(_xlfn.TEXTSPLIT($J25,"/"),4)),"該当なし",INDEX(_xlfn.TEXTSPLIT($J25,"/"),4))} -> 01_HULFT
A26: =ROW()-2 -> 24 | B26: イベント送信_HULFT送信 | C26: /GFOOT/10_日次/31_店舗/03_自動売変_商品マスタ事前確認 | D26: 7FFFA710 イベント送信_HULFT送信 | E26: JP1イベント送信 | F26: 7FFFA710 | H26: =IF(ISERROR(VLOOKUP(F26,'(参考)イベント受信待ち'!A:F,2,FALSE)),"該当無し",VLOOKUP(F26,'(参考)イベント受信待ち'!A:F,2,FALSE)) -> 64 | I26: =IF(ISERROR(VLOOKUP(F26,'(参考)イベント受信待ち'!A:F,3,FALSE)),"該当無し",VLOOKUP(F26,'(参考)イベント受信待ち'!A:F,3,FALSE)) -> ASM発注検収返品データ_7FFFA710 | J26: =IF(ISERROR(VLOOKUP(F26,'(参考)イベント受信待ち'!A:F,4,FALSE)),"該当無し",VLOOKUP(F26,'(参考)イベント受信待ち'!A:F,4,FALSE)) -> /GFOOT/10_日次/N2910_日次監視 | M26: {=INDEX(_xlfn.TEXTSPLIT($C26,"/"),2)} -> GFOOT | N26: {=INDEX(_xlfn.TEXTSPLIT($C26,"/"),3)} -> 10_日次 | O26: {=INDEX(_xlfn.TEXTSPLIT($C26,"/"),4)} -> 31_店舗 | Q26: {=IF(ISERROR(INDEX(_xlfn.TEXTSPLIT($J26,"/"),2)),"該当なし",INDEX(_xlfn.TEXTSPLIT($J26,"/"),2))} -> GFOOT | R26: {=IF(ISERROR(INDEX(_xlfn.TEXTSPLIT($J26,"/"),3)),"該当なし",INDEX(_xlfn.TEXTSPLIT($J26,"/"),3))} -> 10_日次 | S26: {=IF(ISERROR(INDEX(_xlfn.TEXTSPLIT($J26,"/"),4)),"該当なし",INDEX(_xlfn.TEXTSPLIT($J26,"/"),4))} -> N2910_日次監視
A27: =ROW()-2 -> 25 | B27: AgileWorks->DWHコピー_更新完了 | C27: /GFOOT/10_日次/70_WorkFlow/10_返品・事故伝・実在庫訂正 | D27: 7FFFA500 受信_売上・店舗BO・WEB申請先行ジョブ | E27: JP1イベント送信 | F27: 7FFFA500 | H27: =IF(ISERROR(VLOOKUP(F27,'(参考)イベント受信待ち'!A:F,2,FALSE)),"該当無し",VLOOKUP(F27,'(参考)イベント受信待ち'!A:F,2,FALSE)) -> 58 | I27: =IF(ISERROR(VLOOKUP(F27,'(参考)イベント受信待ち'!A:F,3,FALSE)),"該当無し",VLOOKUP(F27,'(参考)イベント受信待ち'!A:F,3,FALSE)) -> AgileWorks_データ連携完了 | J27: =IF(ISERROR(VLOOKUP(F27,'(参考)イベント受信待ち'!A:F,4,FALSE)),"該当無し",VLOOKUP(F27,'(参考)イベント受信待ち'!A:F,4,FALSE)) -> /GFOOT/10_日次/N0100_02_日次/受信_売上・店舗BO・WEB申請 | M27: {=INDEX(_xlfn.TEXTSPLIT($C27,"/"),2)} -> GFOOT | N27: {=INDEX(_xlfn.TEXTSPLIT($C27,"/"),3)} -> 10_日次 | O27: {=INDEX(_xlfn.TEXTSPLIT($C27,"/"),4)} -> 70_WorkFlow | Q27: {=IF(ISERROR(INDEX(_xlfn.TEXTSPLIT($J27,"/"),2)),"該当なし",INDEX(_xlfn.TEXTSPLIT($J27,"/"),2))} -> GFOOT | R27: {=IF(ISERROR(INDEX(_xlfn.TEXTSPLIT($J27,"/"),3)),"該当なし",INDEX(_xlfn.TEXTSPLIT($J27,"/"),3))} -> 10_日次 | S27: {=IF(ISERROR(INDEX(_xlfn.TEXTSPLIT($J27,"/"),4)),"該当なし",INDEX(_xlfn.TEXTSPLIT($J27,"/"),4))} -> N0100_02_日次
A28: =ROW()-2 -> 26 | B28: 新JP1イベント送信_002 | C28: /GFOOT/10_日次/N0100_01_日次_APVマスタデータ | D28: 7FFFA002 | E28: JP1イベント送信 | F28: 7FFFA002 | H28: =IF(ISERROR(VLOOKUP(F28,'(参考)イベント受信待ち'!A:F,2,FALSE)),"該当無し",VLOOKUP(F28,'(参考)イベント受信待ち'!A:F,2,FALSE)) -> 1 | I28: =IF(ISERROR(VLOOKUP(F28,'(参考)イベント受信待ち'!A:F,3,FALSE)),"該当無し",VLOOKUP(F28,'(参考)イベント受信待ち'!A:F,3,FALSE)) -> APVマスタデータ出力完了_002 | J28: =IF(ISERROR(VLOOKUP(F28,'(参考)イベント受信待ち'!A:F,4,FALSE)),"該当無し",VLOOKUP(F28,'(参考)イベント受信待ち'!A:F,4,FALSE)) -> /GFOOT/10_日次/01_HULFT/配信_11_AEON_商品マスタ | M28: {=INDEX(_xlfn.TEXTSPLIT($C28,"/"),2)} -> GFOOT | N28: {=INDEX(_xlfn.TEXTSPLIT($C28,"/"),3)} -> 10_日次 | O28: {=INDEX(_xlfn.TEXTSPLIT($C28,"/"),4)} -> N0100_01_日次_APVマスタデータ | Q28: {=IF(ISERROR(INDEX(_xlfn.TEXTSPLIT($J28,"/"),2)),"該当なし",INDEX(_xlfn.TEXTSPLIT($J28,"/"),2))} -> GFOOT | R28: {=IF(ISERROR(INDEX(_xlfn.TEXTSPLIT($J28,"/"),3)),"該当なし",INDEX(_xlfn.TEXTSPLIT($J28,"/"),3))} -> 10_日次 | S28: {=IF(ISERROR(INDEX(_xlfn.TEXTSPLIT($J28,"/"),4)),"該当なし",INDEX(_xlfn.TEXTSPLIT($J28,"/"),4))} -> 01_HULFT
... A48: =ROW()-2 -> 46 | B48: JP1イベント送信 | C48: /GFOOT/10_日次/N3010_NAIS監視 | D48: 7FFFA299_NAIS処理終了 | E48: JP1イベント送信 | F48: 7FFFA299 | H48: =IF(ISERROR(VLOOKUP(F48,'(参考)イベント受信待ち'!A:F,2,FALSE)),"該当無し",VLOOKUP(F48,'(参考)イベント受信待ち'!A:F,2,FALSE)) -> 37 | I48: =IF(ISERROR(VLOOKUP(F48,'(参考)イベント受信待ち'!A:F,3,FALSE)),"該当無し",VLOOKUP(F48,'(参考)イベント受信待ち'!A:F,3,FALSE)) -> 受299_AUTOMAINOK_DWH更新トリガ | J48: =IF(ISERROR(VLOOKUP(F48,'(参考)イベント受信待ち'!A:F,4,FALSE)),"該当無し",VLOOKUP(F48,'(参考)イベント受信待ち'!A:F,4,FALSE)) -> /GFOOT/10_日次/10_DWH/16_DWH_NIS関連処理 | M48: {=INDEX(_xlfn.TEXTSPLIT($C48,"/"),2)} -> GFOOT | N48: {=INDEX(_xlfn.TEXTSPLIT($C48,"/"),3)} -> 10_日次 | O48: {=INDEX(_xlfn.TEXTSPLIT($C48,"/"),4)} -> N3010_NAIS監視 | Q48: {=IF(ISERROR(INDEX(_xlfn.TEXTSPLIT($J48,"/"),2)),"該当なし",INDEX(_xlfn.TEXTSPLIT($J48,"/"),2))} -> GFOOT | R48: {=IF(ISERROR(INDEX(_xlfn.TEXTSPLIT($J48,"/"),3)),"該当なし",INDEX(_xlfn.TEXTSPLIT($J48,"/"),3))} -> 10_日次 | S48: {=IF(ISERROR(INDEX(_xlfn.TEXTSPLIT($J48,"/"),4)),"該当なし",INDEX(_xlfn.TEXTSPLIT($J48,"/"),4))} -> 10_DWH
B49: # | C49: 46199.796
